Workbook

Sheet 설정
A1: 기간 | B1: 순번(1=가장 최근 주)
A2: 1주 전 | B2: 2
A3: 4주 전 | B3: 5
A4: 8주 전 | B4: 9
A5: 12주 전 | B5: 13
A6: 52주 전 | B6: 53
A7: 104주 전 | B7: 105
A10: 주봉 기준입니다. 일봉이면 순번을 바꾸세요(예: 1주 전=6). 순번은 종목별 최신 일자부터 1,2,3 으로 매겨집니다.
A12: ※ 현재 데이터는 가짜 샘플입니다. 실제 시세가 아닙니다.

Sheet 데이터
A1: 종목명 | B1: 일자 | C1: 종가 | D1: 거래량 | E1: 순번 | G1: A~D열에 붙여 넣고, E열 수식은 아래로 복사하세요.
A2: 샘플종목01 | B2: 45555 | C2: 70591 | D2: 1315279 | E2: =IF(A2="","",COUNTIFS($A$2:$A$20000,A2,$B$2:$B$20000,">"&B2)+1)
A3: 샘플종목01 | B3: 45562 | C3: 74060 | D3: 9090608 | E3: =IF(A3="","",COUNTIFS($A$2:$A$20000,A3,$B$2:$B$20000,">"&B3)+1)
A4: 샘플종목01 | B4: 45569 | C4: 77459 | D4: 8613358 | E4: =IF(A4="","",COUNTIFS($A$2:$A$20000,A4,$B$2:$B$20000,">"&B4)+1)
A5: 샘플종목01 | B5: 45576 | C5: 79898 | D5: 3702037 | E5: =IF(A5="","",COUNTIFS($A$2:$A$20000,A5,$B$2:$B$20000,">"&B5)+1)
A6: 샘플종목01 | B6: 45583 | C6: 83372 | D6: 1271979 | E6: =IF(A6="","",COUNTIFS($A$2:$A$20000,A6,$B$2:$B$20000,">"&B6)+1)
A7: 샘플종목01 | B7: 45590 | C7: 84369 | D7: 4137655 | E7: =IF(A7="","",COUNTIFS($A$2:$A$20000,A7,$B$2:$B$20000,">"&B7)+1)
A8: 샘플종목01 | B8: 45597 | C8: 87524 | D8: 9586738 | E8: =IF(A8="","",COUNTIFS($A$2:$A$20000,A8,$B$2:$B$20000,">"&B8)+1)
A9: 샘플종목01 | B9: 45604 | C9: 89685 | D9: 2177052 | E9: =IF(A9="","",COUNTIFS($A$2:$A$20000,A9,$B$2:$B$20000,">"&B9)+1)
A10: 샘플종목01 | B10: 45611 | C10: 94654 | D10: 9881064 | E10: =IF(A10="","",COUNTIFS($A$2:$A$20000,A10,$B$2:$B$20000,">"&B10)+1)
A11: 샘플종목01 | B11: 45618 | C11: 93111 | D11: 1137872 | E11: =IF(A11="","",COUNTIFS($A$2:$A$20000,A11,$B$2:$B$20000,">"&B11)+1)
A12: 샘플종목01 | B12: 45625 | C12: 89984 | D12: 3809137 | E12: =IF(A12="","",COUNTIFS($A$2:$A$20000,A12,$B$2:$B$20000,">"&B12)+1)
A13: 샘플종목01 | B13: 45632 | C13: 88479 | D13: 881527 | E13: =IF(A13="","",COUNTIFS($A$2:$A$20000,A13,$B$2:$B$20000,">"&B13)+1)
... A3301: 샘플종목30 | B3301: 46318 | C3301: 100423 | D3301: 6560313 | E3301: =IF(A3301="","",COUNTIFS($A$2:$A$20000,A3301,$B$2:$B$20000,">"&B3301)+1)

Sheet 계산
A1: 종목명 | B1: 현재가 | C1: 1주 전 대비 | D1: 4주 전 대비 | E1: 8주 전 대비 | F1: 12주 전 대비 | G1: 52주 전 대비 | H1: 104주 전 대비 | J1: 정렬키 1주 전 | K1: 정렬키 4주 전 | L1: 정렬키 8주 전 | M1: 정렬키 12주 전 | N1: 정렬키 52주 전 | O1: 정렬키 104주 전
A2: 샘플종목01 | B2: =IF($A2="","",IF(COUNTIFS(데이터!$A$2:$A$20000,$A2,데이터!$E$2:$E$20000,1)=0,"",SUMIFS(데이터!$C$2:$C$20000,데이터!$A$2:$A$20000,$A2,데이터!$E$2:$E$20000,1))) | C2: =IFERROR(IF(OR($B2="",COUNTIFS(데이터!$A$2:$A$20000,$A2,데이터!$E$2:$E$20000,설정!$B$2)=0),"",$B2/SUMIFS(데이터!$C$2:$C$20000,데이터!$A$2:$A$20000,$A2,데이터!$E$2:$E$20000,설정!$B$2)-1),"") | D2: =IFERROR(IF(OR($B2="",COUNTIFS(데이터!$A$2:$A$20000,$A2,데이터!$E$2:$E$20000,설정!$B$3)=0),"",$B2/SUMIFS(데이터!$C$2:$C$20000,데이터!$A$2:$A$20000,$A2,데이터!$E$2:$E$20000,설정!$B$3)-1),"") | E2: =IFERROR(IF(OR($B2="",COUNTIFS(데이터!$A$2:$A$20000,$A2,데이터!$E$2:$E$20000,설정!$B$4)=0),"",$B2/SUMIFS(데이터!$C$2:$C$20000,데이터!$A$2:$A$20000,$A2,데이터!$E$2:$E$20000,설정!$B$4)-1),"") | F2: =IFERROR(IF(OR($B2="",COUNTIFS(데이터!$A$2:$A$20000,$A2,데이터!$E$2:$E$20000,설정!$B$5)=0),"",$B2/SUMIFS(데이터!$C$2:$C$20000,데이터!$A$2:$A$20000,$A2,데이터!$E$2:$E$20000,설정!$B$5)-1),"") | G2: =IFERROR(IF(OR($B2="",COUNTIFS(데이터!$A$2:$A$20000,$A2,데이터!$E$2:$E$20000,설정!$B$6)=0),"",$B2/SUMIFS(데이터!$C$2:$C$20000,데이터!$A$2:$A$20000,$A2,데이터!$E$2:$E$20000,설정!$B$6)-1),"") | H2: =IFERROR(IF(OR($B2="",COUNTIFS(데이터!$A$2:$A$20000,$A2,데이터!$E$2:$E$20000,설정!$B$7)=0),"",$B2/SUMIFS(데이터!$C$2:$C$20000,데이터!$A$2:$A$20000,$A2,데이터!$E$2:$E$20000,설정!$B$7)-1),"") | J2: =IF(C2="","",C2+ROW()*0.000000001) | K2: =IF(D2="","",D2+ROW()*0.000000001) | L2: =IF(E2="","",E2+ROW()*0.000000001) | M2: =IF(F2="","",F2+ROW()*0.000000001) | N2: =IF(G2="","",G2+ROW()*0.000000001) | O2: =IF(H2="","",H2+ROW()*0.000000001)
A3: 샘플종목02 | B3: =IF($A3="","",IF(COUNTIFS(데이터!$A$2:$A$20000,$A3,데이터!$E$2:$E$20000,1)=0,"",SUMIFS(데이터!$C$2:$C$20000,데이터!$A$2:$A$20000,$A3,데이터!$E$2:$E$20000,1))) | C3: =IFERROR(IF(OR($B3="",COUNTIFS(데이터!$A$2:$A$20000,$A3,데이터!$E$2:$E$20000,설정!$B$2)=0),"",$B3/SUMIFS(데이터!$C$2:$C$20000,데이터!$A$2:$A$20000,$A3,데이터!$E$2:$E$20000,설정!$B$2)-1),"") | D3: =IFERROR(IF(OR($B3="",COUNTIFS(데이터!$A$2:$A$20000,$A3,데이터!$E$2:$E$20000,설정!$B$3)=0),"",$B3/SUMIFS(데이터!$C$2:$C$20000,데이터!$A$2:$A$20000,$A3,데이터!$E$2:$E$20000,설정!$B$3)-1),"") | E3: =IFERROR(IF(OR($B3="",COUNTIFS(데이터!$A$2:$A$20000,$A3,데이터!$E$2:$E$20000,설정!$B$4)=0),"",$B3/SUMIFS(데이터!$C$2:$C$20000,데이터!$A$2:$A$20000,$A3,데이터!$E$2:$E$20000,설정!$B$4)-1),"") | F3: =IFERROR(IF(OR($B3="",COUNTIFS(데이터!$A$2:$A$20000,$A3,데이터!$E$2:$E$20000,설정!$B$5)=0),"",$B3/SUMIFS(데이터!$C$2:$C$20000,데이터!$A$2:$A$20000,$A3,데이터!$E$2:$E$20000,설정!$B$5)-1),"") | G3: =IFERROR(IF(OR($B3="",COUNTIFS(데이터!$A$2:$A$20000,$A3,데이터!$E$2:$E$20000,설정!$B$6)=0),"",$B3/SUMIFS(데이터!$C$2:$C$20000,데이터!$A$2:$A$20000,$A3,데이터!$E$2:$E$20000,설정!$B$6)-1),"") | H3: =IFERROR(IF(OR($B3="",COUNTIFS(데이터!$A$2:$A$20000,$A3,데이터!$E$2:$E$20000,설정!$B$7)=0),"",$B3/SUMIFS(데이터!$C$2:$C$20000,데이터!$A$2:$A$20000,$A3,데이터!$E$2:$E$20000,설정!$B$7)-1),"") | J3: =IF(C3="","",C3+ROW()*0.000000001) | K3: =IF(D3="","",D3+ROW()*0.000000001) | L3: =IF(E3="","",E3+ROW()*0.000000001) | M3: =IF(F3="","",F3+ROW()*0.000000001) | N3: =IF(G3="","",G3+ROW()*0.000000001) | O3: =IF(H3="","",H3+ROW()*0.000000001)
A4: 샘플종목03 | B4: =IF($A4="","",IF(COUNTIFS(데이터!$A$2:$A$20000,$A4,데이터!$E$2:$E$20000,1)=0,"",SUMIFS(데이터!$C$2:$C$20000,데이터!$A$2:$A$20000,$A4,데이터!$E$2:$E$20000,1))) | C4: =IFERROR(IF(OR($B4="",COUNTIFS(데이터!$A$2:$A$20000,$A4,데이터!$E$2:$E$20000,설정!$B$2)=0),"",$B4/SUMIFS(데이터!$C$2:$C$20000,데이터!$A$2:$A$20000,$A4,데이터!$E$2:$E$20000,설정!$B$2)-1),"") | D4: =IFERROR(IF(OR($B4="",COUNTIFS(데이터!$A$2:$A$20000,$A4,데이터!$E$2:$E$20000,설정!$B$3)=0),"",$B4/SUMIFS(데이터!$C$2:$C$20000,데이터!$A$2:$A$20000,$A4,데이터!$E$2:$E$20000,설정!$B$3)-1),"") | E4: =IFERROR(IF(OR($B4="",COUNTIFS(데이터!$A$2:$A$20000,$A4,데이터!$E$2:$E$20000,설정!$B$4)=0),"",$B4/SUMIFS(데이터!$C$2:$C$20000,데이터!$A$2:$A$20000,$A4,데이터!$E$2:$E$20000,설정!$B$4)-1),"") | F4: =IFERROR(IF(OR($B4="",COUNTIFS(데이터!$A$2:$A$20000,$A4,데이터!$E$2:$E$20000,설정!$B$5)=0),"",$B4/SUMIFS(데이터!$C$2:$C$20000,데이터!$A$2:$A$20000,$A4,데이터!$E$2:$E$20000,설정!$B$5)-1),"") | G4: =IFERROR(IF(OR($B4="",COUNTIFS(데이터!$A$2:$A$20000,$A4,데이터!$E$2:$E$20000,설정!$B$6)=0),"",$B4/SUMIFS(데이터!$C$2:$C$20000,데이터!$A$2:$A$20000,$A4,데이터!$E$2:$E$20000,설정!$B$6)-1),"") | H4: =IFERROR(IF(OR($B4="",COUNTIFS(데이터!$A$2:$A$20000,$A4,데이터!$E$2:$E$20000,설정!$B$7)=0),"",$B4/SUMIFS(데이터!$C$2:$C$20000,데이터!$A$2:$A$20000,$A4,데이터!$E$2:$E$20000,설정!$B$7)-1),"") | J4: =IF(C4="","",C4+ROW()*0.000000001) | K4: =IF(D4="","",D4+ROW()*0.000000001) | L4: =IF(E4="","",E4+ROW()*0.000000001) | M4: =IF(F4="","",F4+ROW()*0.000000001) | N4: =IF(G4="","",G4+ROW()*0.000000001) | O4: =IF(H4="","",H4+ROW()*0.000000001)
A5: 샘플종목04 | B5: =IF($A5="","",IF(COUNTIFS(데이터!$A$2:$A$20000,$A5,데이터!$E$2:$E$20000,1)=0,"",SUMIFS(데이터!$C$2:$C$20000,데이터!$A$2:$A$20000,$A5,데이터!$E$2:$E$20000,1))) | C5: =IFERROR(IF(OR($B5="",COUNTIFS(데이터!$A$2:$A$20000,$A5,데이터!$E$2:$E$20000,설정!$B$2)=0),"",$B5/SUMIFS(데이터!$C$2:$C$20000,데이터!$A$2:$A$20000,$A5,데이터!$E$2:$E$20000,설정!$B$2)-1),"") | D5: =IFERROR(IF(OR($B5="",COUNTIFS(데이터!$A$2:$A$20000,$A5,데이터!$E$2:$E$20000,설정!$B$3)=0),"",$B5/SUMIFS(데이터!$C$2:$C$20000,데이터!$A$2:$A$20000,$A5,데이터!$E$2:$E$20000,설정!$B$3)-1),"") | E5: =IFERROR(IF(OR($B5="",COUNTIFS(데이터!$A$2:$A$20000,$A5,데이터!$E$2:$E$20000,설정!$B$4)=0),"",$B5/SUMIFS(데이터!$C$2:$C$20000,데이터!$A$2:$A$20000,$A5,데이터!$E$2:$E$20000,설정!$B$4)-1),"") | F5: =IFERROR(IF(OR($B5="",COUNTIFS(데이터!$A$2:$A$20000,$A5,데이터!$E$2:$E$20000,설정!$B$5)=0),"",$B5/SUMIFS(데이터!$C$2:$C$20000,데이터!$A$2:$A$20000,$A5,데이터!$E$2:$E$20000,설정!$B$5)-1),"") | G5: =IFERROR(IF(OR($B5="",COUNTIFS(데이터!$A$2:$A$20000,$A5,데이터!$E$2:$E$20000,설정!$B$6)=0),"",$B5/SUMIFS(데이터!$C$2:$C$20000,데이터!$A$2:$A$20000,$A5,데이터!$E$2:$E$20000,설정!$B$6)-1),"") | H5: =IFERROR(IF(OR($B5="",COUNTIFS(데이터!$A$2:$A$20000,$A5,데이터!$E$2:$E$20000,설정!$B$7)=0),"",$B5/SUMIFS(데이터!$C$2:$C$20000,데이터!$A$2:$A$20000,$A5,데이터!$E$2:$E$20000,설정!$B$7)-1),"") | J5: =IF(C5="","",C5+ROW()*0.000000001) | K5: =IF(D5="","",D5+ROW()*0.000000001) | L5: =IF(E5="","",E5+ROW()*0.000000001) | M5: =IF(F5="","",F5+ROW()*0.000000001) | N5: =IF(G5="","",G5+ROW()*0.000000001) | O5: =IF(H5="","",H5+ROW()*0.000000001)
A6: 샘플종목05 | B6: =IF($A6="","",IF(COUNTIFS(데이터!$A$2:$A$20000,$A6,데이터!$E$2:$E$20000,1)=0,"",SUMIFS(데이터!$C$2:$C$20000,데이터!$A$2:$A$20000,$A6,데이터!$E$2:$E$20000,1))) | C6: =IFERROR(IF(OR($B6="",COUNTIFS(데이터!$A$2:$A$20000,$A6,데이터!$E$2:$E$20000,설정!$B$2)=0),"",$B6/SUMIFS(데이터!$C$2:$C$20000,데이터!$A$2:$A$20000,$A6,데이터!$E$2:$E$20000,설정!$B$2)-1),"") | D6: =IFERROR(IF(OR($B6="",COUNTIFS(데이터!$A$2:$A$20000,$A6,데이터!$E$2:$E$20000,설정!$B$3)=0),"",$B6/SUMIFS(데이터!$C$2:$C$20000,데이터!$A$2:$A$20000,$A6,데이터!$E$2:$E$20000,설정!$B$3)-1),"") | E6: =IFERROR(IF(OR($B6="",COUNTIFS(데이터!$A$2:$A$20000,$A6,데이터!$E$2:$E$20000,설정!$B$4)=0),"",$B6/SUMIFS(데이터!$C$2:$C$20000,데이터!$A$2:$A$20000,$A6,데이터!$E$2:$E$20000,설정!$B$4)-1),"") | F6: =IFERROR(IF(OR($B6="",COUNTIFS(데이터!$A$2:$A$20000,$A6,데이터!$E$2:$E$20000,설정!$B$5)=0),"",$B6/SUMIFS(데이터!$C$2:$C$20000,데이터!$A$2:$A$20000,$A6,데이터!$E$2:$E$20000,설정!$B$5)-1),"") | G6: =IFERROR(IF(OR($B6="",COUNTIFS(데이터!$A$2:$A$20000,$A6,데이터!$E$2:$E$20000,설정!$B$6)=0),"",$B6/SUMIFS(데이터!$C$2:$C$20000,데이터!$A$2:$A$20000,$A6,데이터!$E$2:$E$20000,설정!$B$6)-1),"") | H6: =IFERROR(IF(OR($B6="",COUNTIFS(데이터!$A$2:$A$20000,$A6,데이터!$E$2:$E$20000,설정!$B$7)=0),"",$B6/SUMIFS(데이터!$C$2:$C$20000,데이터!$A$2:$A$20000,$A6,데이터!$E$2:$E$20000,설정!$B$7)-1),"") | J6: =IF(C6="","",C6+ROW()*0.000000001) | K6: =IF(D6="","",D6+ROW()*0.000000001) | L6: =IF(E6="","",E6+ROW()*0.000000001) | M6: =IF(F6="","",F6+ROW()*0.000000001) | N6: =IF(G6="","",G6+ROW()*0.000000001) | O6: =IF(H6="","",H6+ROW()*0.000000001)
A7: 샘플종목06 | B7: =IF($A7="","",IF(COUNTIFS(데이터!$A$2:$A$20000,$A7,데이터!$E$2:$E$20000,1)=0,"",SUMIFS(데이터!$C$2:$C$20000,데이터!$A$2:$A$20000,$A7,데이터!$E$2:$E$20000,1))) | C7: =IFERROR(IF(OR($B7="",COUNTIFS(데이터!$A$2:$A$20000,$A7,데이터!$E$2:$E$20000,설정!$B$2)=0),"",$B7/SUMIFS(데이터!$C$2:$C$20000,데이터!$A$2:$A$20000,$A7,데이터!$E$2:$E$20000,설정!$B$2)-1),"") | D7: =IFERROR(IF(OR($B7="",COUNTIFS(데이터!$A$2:$A$20000,$A7,데이터!$E$2:$E$20000,설정!$B$3)=0),"",$B7/SUMIFS(데이터!$C$2:$C$20000,데이터!$A$2:$A$20000,$A7,데이터!$E$2:$E$20000,설정!$B$3)-1),"") | E7: =IFERROR(IF(OR($B7="",COUNTIFS(데이터!$A$2:$A$20000,$A7,데이터!$E$2:$E$20000,설정!$B$4)=0),"",$B7/SUMIFS(데이터!$C$2:$C$20000,데이터!$A$2:$A$20000,$A7,데이터!$E$2:$E$20000,설정!$B$4)-1),"") | F7: =IFERROR(IF(OR($B7="",COUNTIFS(데이터!$A$2:$A$20000,$A7,데이터!$E$2:$E$20000,설정!$B$5)=0),"",$B7/SUMIFS(데이터!$C$2:$C$20000,데이터!$A$2:$A$20000,$A7,데이터!$E$2:$E$20000,설정!$B$5)-1),"") | G7: =IFERROR(IF(OR($B7="",COUNTIFS(데이터!$A$2:$A$20000,$A7,데이터!$E$2:$E$20000,설정!$B$6)=0),"",$B7/SUMIFS(데이터!$C$2:$C$20000,데이터!$A$2:$A$20000,$A7,데이터!$E$2:$E$20000,설정!$B$6)-1),"") | H7: =IFERROR(IF(OR($B7="",COUNTIFS(데이터!$A$2:$A$20000,$A7,데이터!$E$2:$E$20000,설정!$B$7)=0),"",$B7/SUMIFS(데이터!$C$2:$C$20000,데이터!$A$2:$A$20000,$A7,데이터!$E$2:$E$20000,설정!$B$7)-1),"") | J7: =IF(C7="","",C7+ROW()*0.000000001) | K7: =IF(D7="","",D7+ROW()*0.000000001) | L7: =IF(E7="","",E7+ROW()*0.000000001) | M7: =IF(F7="","",F7+ROW()*0.000000001) | N7: =IF(G7="","",G7+ROW()*0.000000001) | O7: =IF(H7="","",H7+ROW()*0.000000001)
A8: 샘플종목07 | B8: =IF($A8="","",IF(COUNTIFS(데이터!$A$2:$A$20000,$A8,데이터!$E$2:$E$20000,1)=0,"",SUMIFS(데이터!$C$2:$C$20000,데이터!$A$2:$A$20000,$A8,데이터!$E$2:$E$20000,1))) | C8: =IFERROR(IF(OR($B8="",COUNTIFS(데이터!$A$2:$A$20000,$A8,데이터!$E$2:$E$20000,설정!$B$2)=0),"",$B8/SUMIFS(데이터!$C$2:$C$20000,데이터!$A$2:$A$20000,$A8,데이터!$E$2:$E$20000,설정!$B$2)-1),"") | D8: =IFERROR(IF(OR($B8="",COUNTIFS(데이터!$A$2:$A$20000,$A8,데이터!$E$2:$E$20000,설정!$B$3)=0),"",$B8/SUMIFS(데이터!$C$2:$C$20000,데이터!$A$2:$A$20000,$A8,데이터!$E$2:$E$20000,설정!$B$3)-1),"") | E8: =IFERROR(IF(OR($B8="",COUNTIFS(데이터!$A$2:$A$20000,$A8,데이터!$E$2:$E$20000,설정!$B$4)=0),"",$B8/SUMIFS(데이터!$C$2:$C$20000,데이터!$A$2:$A$20000,$A8,데이터!$E$2:$E$20000,설정!$B$4)-1),"") | F8: =IFERROR(IF(OR($B8="",COUNTIFS(데이터!$A$2:$A$20000,$A8,데이터!$E$2:$E$20000,설정!$B$5)=0),"",$B8/SUMIFS(데이터!$C$2:$C$20000,데이터!$A$2:$A$20000,$A8,데이터!$E$2:$E$20000,설정!$B$5)-1),"") | G8: =IFERROR(IF(OR($B8="",COUNTIFS(데이터!$A$2:$A$20000,$A8,데이터!$E$2:$E$20000,설정!$B$6)=0),"",$B8/SUMIFS(데이터!$C$2:$C$20000,데이터!$A$2:$A$20000,$A8,데이터!$E$2:$E$20000,설정!$B$6)-1),"") | H8: =IFERROR(IF(OR($B8="",COUNTIFS(데이터!$A$2:$A$20000,$A8,데이터!$E$2:$E$20000,설정!$B$7)=0),"",$B8/SUMIFS(데이터!$C$2:$C$20000,데이터!$A$2:$A$20000,$A8,데이터!$E$2:$E$20000,설정!$B$7)-1),"") | J8: =IF(C8="","",C8+ROW()*0.000000001) | K8: =IF(D8="","",D8+ROW()*0.000000001) | L8: =IF(E8="","",E8+ROW()*0.000000001) | M8: =IF(F8="","",F8+ROW()*0.000000001) | N8: =IF(G8="","",G8+ROW()*0.000000001) | O8: =IF(H8="","",H8+ROW()*0.000000001)
A9: 샘플종목08 | B9: =IF($A9="","",IF(COUNTIFS(데이터!$A$2:$A$20000,$A9,데이터!$E$2:$E$20000,1)=0,"",SUMIFS(데이터!$C$2:$C$20000,데이터!$A$2:$A$20000,$A9,데이터!$E$2:$E$20000,1))) | C9: =IFERROR(IF(OR($B9="",COUNTIFS(데이터!$A$2:$A$20000,$A9,데이터!$E$2:$E$20000,설정!$B$2)=0),"",$B9/SUMIFS(데이터!$C$2:$C$20000,데이터!$A$2:$A$20000,$A9,데이터!$E$2:$E$20000,설정!$B$2)-1),"") | D9: =IFERROR(IF(OR($B9="",COUNTIFS(데이터!$A$2:$A$20000,$A9,데이터!$E$2:$E$20000,설정!$B$3)=0),"",$B9/SUMIFS(데이터!$C$2:$C$20000,데이터!$A$2:$A$20000,$A9,데이터!$E$2:$E$20000,설정!$B$3)-1),"") | E9: =IFERROR(IF(OR($B9="",COUNTIFS(데이터!$A$2:$A$20000,$A9,데이터!$E$2:$E$20000,설정!$B$4)=0),"",$B9/SUMIFS(데이터!$C$2:$C$20000,데이터!$A$2:$A$20000,$A9,데이터!$E$2:$E$20000,설정!$B$4)-1),"") | F9: =IFERROR(IF(OR($B9="",COUNTIFS(데이터!$A$2:$A$20000,$A9,데이터!$E$2:$E$20000,설정!$B$5)=0),"",$B9/SUMIFS(데이터!$C$2:$C$20000,데이터!$A$2:$A$20000,$A9,데이터!$E$2:$E$20000,설정!$B$5)-1),"") | G9: =IFERROR(IF(OR($B9="",COUNTIFS(데이터!$A$2:$A$20000,$A9,데이터!$E$2:$E$20000,설정!$B$6)=0),"",$B9/SUMIFS(데이터!$C$2:$C$20000,데이터!$A$2:$A$20000,$A9,데이터!$E$2:$E$20000,설정!$B$6)-1),"") | H9: =IFERROR(IF(OR($B9="",COUNTIFS(데이터!$A$2:$A$20000,$A9,데이터!$E$2:$E$20000,설정!$B$7)=0),"",$B9/SUMIFS(데이터!$C$2:$C$20000,데이터!$A$2:$A$20000,$A9,데이터!$E$2:$E$20000,설정!$B$7)-1),"") | J9: =IF(C9="","",C9+ROW()*0.000000001) | K9: =IF(D9="","",D9+ROW()*0.000000001) | L9: =IF(E9="","",E9+ROW()*0.000000001) | M9: =IF(F9="","",F9+ROW()*0.000000001) | N9: =IF(G9="","",G9+ROW()*0.000000001) | O9: =IF(H9="","",H9+ROW()*0.000000001)
A10: 샘플종목09 | B10: =IF($A10="","",IF(COUNTIFS(데이터!$A$2:$A$20000,$A10,데이터!$E$2:$E$20000,1)=0,"",SUMIFS(데이터!$C$2:$C$20000,데이터!$A$2:$A$20000,$A10,데이터!$E$2:$E$20000,1))) | C10: =IFERROR(IF(OR($B10="",COUNTIFS(데이터!$A$2:$A$20000,$A10,데이터!$E$2:$E$20000,설정!$B$2)=0),"",$B10/SUMIFS(데이터!$C$2:$C$20000,데이터!$A$2:$A$20000,$A10,데이터!$E$2:$E$20000,설정!$B$2)-1),"") | D10: =IFERROR(IF(OR($B10="",COUNTIFS(데이터!$A$2:$A$20000,$A10,데이터!$E$2:$E$20000,설정!$B$3)=0),"",$B10/SUMIFS(데이터!$C$2:$C$20000,데이터!$A$2:$A$20000,$A10,데이터!$E$2:$E$20000,설정!$B$3)-1),"") | E10: =IFERROR(IF(OR($B10="",COUNTIFS(데이터!$A$2:$A$20000,$A10,데이터!$E$2:$E$20000,설정!$B$4)=0),"",$B10/SUMIFS(데이터!$C$2:$C$20000,데이터!$A$2:$A$20000,$A10,데이터!$E$2:$E$20000,설정!$B$4)-1),"") | F10: =IFERROR(IF(OR($B10="",COUNTIFS(데이터!$A$2:$A$20000,$A10,데이터!$E$2:$E$20000,설정!$B$5)=0),"",$B10/SUMIFS(데이터!$C$2:$C$20000,데이터!$A$2:$A$20000,$A10,데이터!$E$2:$E$20000,설정!$B$5)-1),"") | G10: =IFERROR(IF(OR($B10="",COUNTIFS(데이터!$A$2:$A$20000,$A10,데이터!$E$2:$E$20000,설정!$B$6)=0),"",$B10/SUMIFS(데이터!$C$2:$C$20000,데이터!$A$2:$A$20000,$A10,데이터!$E$2:$E$20000,설정!$B$6)-1),"") | H10: =IFERROR(IF(OR($B10="",COUNTIFS(데이터!$A$2:$A$20000,$A10,데이터!$E$2:$E$20000,설정!$B$7)=0),"",$B10/SUMIFS(데이터!$C$2:$C$20000,데이터!$A$2:$A$20000,$A10,데이터!$E$2:$E$20000,설정!$B$7)-1),"") | J10: =IF(C10="","",C10+ROW()*0.000000001) | K10: =IF(D10="","",D10+ROW()*0.000000001) | L10: =IF(E10="","",E10+ROW()*0.000000001) | M10: =IF(F10="","",F10+ROW()*0.000000001) | N10: =IF(G10="","",G10+ROW()*0.000000001) | O10: =IF(H10="","",H10+ROW()*0.000000001)
A11: 샘플종목10 | B11: =IF($A11="","",IF(COUNTIFS(데이터!$A$2:$A$20000,$A11,데이터!$E$2:$E$20000,1)=0,"",SUMIFS(데이터!$C$2:$C$20000,데이터!$A$2:$A$20000,$A11,데이터!$E$2:$E$20000,1))) | C11: =IFERROR(IF(OR($B11="",COUNTIFS(데이터!$A$2:$A$20000,$A11,데이터!$E$2:$E$20000,설정!$B$2)=0),"",$B11/SUMIFS(데이터!$C$2:$C$20000,데이터!$A$2:$A$20000,$A11,데이터!$E$2:$E$20000,설정!$B$2)-1),"") | D11: =IFERROR(IF(OR($B11="",COUNTIFS(데이터!$A$2:$A$20000,$A11,데이터!$E$2:$E$20000,설정!$B$3)=0),"",$B11/SUMIFS(데이터!$C$2:$C$20000,데이터!$A$2:$A$20000,$A11,데이터!$E$2:$E$20000,설정!$B$3)-1),"") | E11: =IFERROR(IF(OR($B11="",COUNTIFS(데이터!$A$2:$A$20000,$A11,데이터!$E$2:$E$20000,설정!$B$4)=0),"",$B11/SUMIFS(데이터!$C$2:$C$20000,데이터!$A$2:$A$20000,$A11,데이터!$E$2:$E$20000,설정!$B$4)-1),"") | F11: =IFERROR(IF(OR($B11="",COUNTIFS(데이터!$A$2:$A$20000,$A11,데이터!$E$2:$E$20000,설정!$B$5)=0),"",$B11/SUMIFS(데이터!$C$2:$C$20000,데이터!$A$2:$A$20000,$A11,데이터!$E$2:$E$20000,설정!$B$5)-1),"") | G11: =IFERROR(IF(OR($B11="",COUNTIFS(데이터!$A$2:$A$20000,$A11,데이터!$E$2:$E$20000,설정!$B$6)=0),"",$B11/SUMIFS(데이터!$C$2:$C$20000,데이터!$A$2:$A$20000,$A11,데이터!$E$2:$E$20000,설정!$B$6)-1),"") | H11: =IFERROR(IF(OR($B11="",COUNTIFS(데이터!$A$2:$A$20000,$A11,데이터!$E$2:$E$20000,설정!$B$7)=0),"",$B11/SUMIFS(데이터!$C$2:$C$20000,데이터!$A$2:$A$20000,$A11,데이터!$E$2:$E$20000,설정!$B$7)-1),"") | J11: =IF(C11="","",C11+ROW()*0.000000001) | K11: =IF(D11="","",D11+ROW()*0.000000001) | L11: =IF(E11="","",E11+ROW()*0.000000001) | M11: =IF(F11="","",F11+ROW()*0.000000001) | N11: =IF(G11="","",G11+ROW()*0.000000001) | O11: =IF(H11="","",H11+ROW()*0.000000001)
A12: 샘플종목11 | B12: =IF($A12="","",IF(COUNTIFS(데이터!$A$2:$A$20000,$A12,데이터!$E$2:$E$20000,1)=0,"",SUMIFS(데이터!$C$2:$C$20000,데이터!$A$2:$A$20000,$A12,데이터!$E$2:$E$20000,1))) | C12: =IFERROR(IF(OR($B12="",COUNTIFS(데이터!$A$2:$A$20000,$A12,데이터!$E$2:$E$20000,설정!$B$2)=0),"",$B12/SUMIFS(데이터!$C$2:$C$20000,데이터!$A$2:$A$20000,$A12,데이터!$E$2:$E$20000,설정!$B$2)-1),"") | D12: =IFERROR(IF(OR($B12="",COUNTIFS(데이터!$A$2:$A$20000,$A12,데이터!$E$2:$E$20000,설정!$B$3)=0),"",$B12/SUMIFS(데이터!$C$2:$C$20000,데이터!$A$2:$A$20000,$A12,데이터!$E$2:$E$20000,설정!$B$3)-1),"") | E12: =IFERROR(IF(OR($B12="",COUNTIFS(데이터!$A$2:$A$20000,$A12,데이터!$E$2:$E$20000,설정!$B$4)=0),"",$B12/SUMIFS(데이터!$C$2:$C$20000,데이터!$A$2:$A$20000,$A12,데이터!$E$2:$E$20000,설정!$B$4)-1),"") | F12: =IFERROR(IF(OR($B12="",COUNTIFS(데이터!$A$2:$A$20000,$A12,데이터!$E$2:$E$20000,설정!$B$5)=0),"",$B12/SUMIFS(데이터!$C$2:$C$20000,데이터!$A$2:$A$20000,$A12,데이터!$E$2:$E$20000,설정!$B$5)-1),"") | G12: =IFERROR(IF(OR($B12="",COUNTIFS(데이터!$A$2:$A$20000,$A12,데이터!$E$2:$E$20000,설정!$B$6)=0),"",$B12/SUMIFS(데이터!$C$2:$C$20000,데이터!$A$2:$A$20000,$A12,데이터!$E$2:$E$20000,설정!$B$6)-1),"") | H12: =IFERROR(IF(OR($B12="",COUNTIFS(데이터!$A$2:$A$20000,$A12,데이터!$E$2:$E$20000,설정!$B$7)=0),"",$B12/SUMIFS(데이터!$C$2:$C$20000,데이터!$A$2:$A$20000,$A12,데이터!$E$2:$E$20000,설정!$B$7)-1),"") | J12: =IF(C12="","",C12+ROW()*0.000000001) | K12: =IF(D12="","",D12+ROW()*0.000000001) | L12: =IF(E12="","",E12+ROW()*0.000000001) | M12: =IF(F12="","",F12+ROW()*0.000000001) | N12: =IF(G12="","",G12+ROW()*0.000000001) | O12: =IF(H12="","",H12+ROW()*0.000000001)
A13: 샘플종목12 | B13: =IF($A13="","",IF(COUNTIFS(데이터!$A$2:$A$20000,$A13,데이터!$E$2:$E$20000,1)=0,"",SUMIFS(데이터!$C$2:$C$20000,데이터!$A$2:$A$20000,$A13,데이터!$E$2:$E$20000,1))) | C13: =IFERROR(IF(OR($B13="",COUNTIFS(데이터!$A$2:$A$20000,$A13,데이터!$E$2:$E$20000,설정!$B$2)=0),"",$B13/SUMIFS(데이터!$C$2:$C$20000,데이터!$A$2:$A$20000,$A13,데이터!$E$2:$E$20000,설정!$B$2)-1),"") | D13: =IFERROR(IF(OR($B13="",COUNTIFS(데이터!$A$2:$A$20000,$A13,데이터!$E$2:$E$20000,설정!$B$3)=0),"",$B13/SUMIFS(데이터!$C$2:$C$20000,데이터!$A$2:$A$20000,$A13,데이터!$E$2:$E$20000,설정!$B$3)-1),"") | E13: =IFERROR(IF(OR($B13="",COUNTIFS(데이터!$A$2:$A$20000,$A13,데이터!$E$2:$E$20000,설정!$B$4)=0),"",$B13/SUMIFS(데이터!$C$2:$C$20000,데이터!$A$2:$A$20000,$A13,데이터!$E$2:$E$20000,설정!$B$4)-1),"") | F13: =IFERROR(IF(OR($B13="",COUNTIFS(데이터!$A$2:$A$20000,$A13,데이터!$E$2:$E$20000,설정!$B$5)=0),"",$B13/SUMIFS(데이터!$C$2:$C$20000,데이터!$A$2:$A$20000,$A13,데이터!$E$2:$E$20000,설정!$B$5)-1),"") | G13: =IFERROR(IF(OR($B13="",COUNTIFS(데이터!$A$2:$A$20000,$A13,데이터!$E$2:$E$20000,설정!$B$6)=0),"",$B13/SUMIFS(데이터!$C$2:$C$20000,데이터!$A$2:$A$20000,$A13,데이터!$E$2:$E$20000,설정!$B$6)-1),"") | H13: =IFERROR(IF(OR($B13="",COUNTIFS(데이터!$A$2:$A$20000,$A13,데이터!$E$2:$E$20000,설정!$B$7)=0),"",$B13/SUMIFS(데이터!$C$2:$C$20000,데이터!$A$2:$A$20000,$A13,데이터!$E$2:$E$20000,설정!$B$7)-1),"") | J13: =IF(C13="","",C13+ROW()*0.000000001) | K13: =IF(D13="","",D13+ROW()*0.000000001) | L13: =IF(E13="","",E13+ROW()*0.000000001) | M13: =IF(F13="","",F13+ROW()*0.000000001) | N13: =IF(G13="","",G13+ROW()*0.000000001) | O13: =IF(H13="","",H13+ROW()*0.000000001)
... A31: 샘플종목30 | B31: =IF($A31="","",IF(COUNTIFS(데이터!$A$2:$A$20000,$A31,데이터!$E$2:$E$20000,1)=0,"",SUMIFS(데이터!$C$2:$C$20000,데이터!$A$2:$A$20000,$A31,데이터!$E$2:$E$20000,1))) | C31: =IFERROR(IF(OR($B31="",COUNTIFS(데이터!$A$2:$A$20000,$A31,데이터!$E$2:$E$20000,설정!$B$2)=0),"",$B31/SUMIFS(데이터!$C$2:$C$20000,데이터!$A$2:$A$20000,$A31,데이터!$E$2:$E$20000,설정!$B$2)-1),"") | D31: =IFERROR(IF(OR($B31="",COUNTIFS(데이터!$A$2:$A$20000,$A31,데이터!$E$2:$E$20000,설정!$B$3)=0),"",$B31/SUMIFS(데이터!$C$2:$C$20000,데이터!$A$2:$A$20000,$A31,데이터!$E$2:$E$20000,설정!$B$3)-1),"") | E31: =IFERROR(IF(OR($B31="",COUNTIFS(데이터!$A$2:$A$20000,$A31,데이터!$E$2:$E$20000,설정!$B$4)=0),"",$B31/SUMIFS(데이터!$C$2:$C$20000,데이터!$A$2:$A$20000,$A31,데이터!$E$2:$E$20000,설정!$B$4)-1),"") | F31: =IFERROR(IF(OR($B31="",COUNTIFS(데이터!$A$2:$A$20000,$A31,데이터!$E$2:$E$20000,설정!$B$5)=0),"",$B31/SUMIFS(데이터!$C$2:$C$20000,데이터!$A$2:$A$20000,$A31,데이터!$E$2:$E$20000,설정!$B$5)-1),"") | G31: =IFERROR(IF(OR($B31="",COUNTIFS(데이터!$A$2:$A$20000,$A31,데이터!$E$2:$E$20000,설정!$B$6)=0),"",$B31/SUMIFS(데이터!$C$2:$C$20000,데이터!$A$2:$A$20000,$A31,데이터!$E$2:$E$20000,설정!$B$6)-1),"") | H31: =IFERROR(IF(OR($B31="",COUNTIFS(데이터!$A$2:$A$20000,$A31,데이터!$E$2:$E$20000,설정!$B$7)=0),"",$B31/SUMIFS(데이터!$C$2:$C$20000,데이터!$A$2:$A$20000,$A31,데이터!$E$2:$E$20000,설정!$B$7)-1),"") | J31: =IF(C31="","",C31+ROW()*0.000000001) | K31: =IF(D31="","",D31+ROW()*0.000000001) | L31: =IF(E31="","",E31+ROW()*0.000000001) | M31: =IF(F31="","",F31+ROW()*0.000000001) | N31: =IF(G31="","",G31+ROW()*0.000000001) | O31: =IF(H31="","",H31+ROW()*0.000000001)
B32: =IF($A32="","",IF(COUNTIFS(데이터!$A$2:$A$20000,$A32,데이터!$E$2:$E$20000,1)=0,"",SUMIFS(데이터!$C$2:$C$20000,데이터!$A$2:$A$20000,$A32,데이터!$E$2:$E$20000,1))) | C32: =IFERROR(IF(OR($B32="",COUNTIFS(데이터!$A$2:$A$20000,$A32,데이터!$E$2:$E$20000,설정!$B$2)=0),"",$B32/SUMIFS(데이터!$C$2:$C$20000,데이터!$A$2:$A$20000,$A32,데이터!$E$2:$E$20000,설정!$B$2)-1),"") | D32: =IFERROR(IF(OR($B32="",COUNTIFS(데이터!$A$2:$A$20000,$A32,데이터!$E$2:$E$20000,설정!$B$3)=0),"",$B32/SUMIFS(데이터!$C$2:$C$20000,데이터!$A$2:$A$20000,$A32,데이터!$E$2:$E$20000,설정!$B$3)-1),"") | E32: =IFERROR(IF(OR($B32="",COUNTIFS(데이터!$A$2:$A$20000,$A32,데이터!$E$2:$E$20000,설정!$B$4)=0),"",$B32/SUMIFS(데이터!$C$2:$C$20000,데이터!$A$2:$A$20000,$A32,데이터!$E$2:$E$20000,설정!$B$4)-1),"") | F32: =IFERROR(IF(OR($B32="",COUNTIFS(데이터!$A$2:$A$20000,$A32,데이터!$E$2:$E$20000,설정!$B$5)=0),"",$B32/SUMIFS(데이터!$C$2:$C$20000,데이터!$A$2:$A$20000,$A32,데이터!$E$2:$E$20000,설정!$B$5)-1),"") | G32: =IFERROR(IF(OR($B32="",COUNTIFS(데이터!$A$2:$A$20000,$A32,데이터!$E$2:$E$20000,설정!$B$6)=0),"",$B32/SUMIFS(데이터!$C$2:$C$20000,데이터!$A$2:$A$20000,$A32,데이터!$E$2:$E$20000,설정!$B$6)-1),"") | H32: =IFERROR(IF(OR($B32="",COUNTIFS(데이터!$A$2:$A$20000,$A32,데이터!$E$2:$E$20000,설정!$B$7)=0),"",$B32/SUMIFS(데이터!$C$2:$C$20000,데이터!$A$2:$A$20000,$A32,데이터!$E$2:$E$20000,설정!$B$7)-1),"") | J32: =IF(C32="","",C32+ROW()*0.000000001) | K32: =IF(D32="","",D32+ROW()*0.000000001) | L32: =IF(E32="","",E32+ROW()*0.000000001) | M32: =IF(F32="","",F32+ROW()*0.000000001) | N32: =IF(G32="","",G32+ROW()*0.000000001) | O32: =IF(H32="","",H32+ROW()*0.000000001)
B33: =IF($A33="","",IF(COUNTIFS(데이터!$A$2:$A$20000,$A33,데이터!$E$2:$E$20000,1)=0,"",SUMIFS(데이터!$C$2:$C$20000,데이터!$A$2:$A$20000,$A33,데이터!$E$2:$E$20000,1))) | C33: =IFERROR(IF(OR($B33="",COUNTIFS(데이터!$A$2:$A$20000,$A33,데이터!$E$2:$E$20000,설정!$B$2)=0),"",$B33/SUMIFS(데이터!$C$2:$C$20000,데이터!$A$2:$A$20000,$A33,데이터!$E$2:$E$20000,설정!$B$2)-1),"") | D33: =IFERROR(IF(OR($B33="",COUNTIFS(데이터!$A$2:$A$20000,$A33,데이터!$E$2:$E$20000,설정!$B$3)=0),"",$B33/SUMIFS(데이터!$C$2:$C$20000,데이터!$A$2:$A$20000,$A33,데이터!$E$2:$E$20000,설정!$B$3)-1),"") | E33: =IFERROR(IF(OR($B33="",COUNTIFS(데이터!$A$2:$A$20000,$A33,데이터!$E$2:$E$20000,설정!$B$4)=0),"",$B33/SUMIFS(데이터!$C$2:$C$20000,데이터!$A$2:$A$20000,$A33,데이터!$E$2:$E$20000,설정!$B$4)-1),"") | F33: =IFERROR(IF(OR($B33="",COUNTIFS(데이터!$A$2:$A$20000,$A33,데이터!$E$2:$E$20000,설정!$B$5)=0),"",$B33/SUMIFS(데이터!$C$2:$C$20000,데이터!$A$2:$A$20000,$A33,데이터!$E$2:$E$20000,설정!$B$5)-1),"") | G33: =IFERROR(IF(OR($B33="",COUNTIFS(데이터!$A$2:$A$20000,$A33,데이터!$E$2:$E$20000,설정!$B$6)=0),"",$B33/SUMIFS(데이터!$C$2:$C$20000,데이터!$A$2:$A$20000,$A33,데이터!$E$2:$E$20000,설정!$B$6)-1),"") | H33: =IFERROR(IF(OR($B33="",COUNTIFS(데이터!$A$2:$A$20000,$A33,데이터!$E$2:$E$20000,설정!$B$7)=0),"",$B33/SUMIFS(데이터!$C$2:$C$20000,데이터!$A$2:$A$20000,$A33,데이터!$E$2:$E$20000,설정!$B$7)-1),"") | J33: =IF(C33="","",C33+ROW()*0.000000001) | K33: =IF(D33="","",D33+ROW()*0.000000001) | L33: =IF(E33="","",E33+ROW()*0.000000001) | M33: =IF(F33="","",F33+ROW()*0.000000001) | N33: =IF(G33="","",G33+ROW()*0.000000001) | O33: =IF(H33="","",H33+ROW()*0.000000001)
B34: =IF($A34="","",IF(COUNTIFS(데이터!$A$2:$A$20000,$A34,데이터!$E$2:$E$20000,1)=0,"",SUMIFS(데이터!$C$2:$C$20000,데이터!$A$2:$A$20000,$A34,데이터!$E$2:$E$20000,1))) | C34: =IFERROR(IF(OR($B34="",COUNTIFS(데이터!$A$2:$A$20000,$A34,데이터!$E$2:$E$20000,설정!$B$2)=0),"",$B34/SUMIFS(데이터!$C$2:$C$20000,데이터!$A$2:$A$20000,$A34,데이터!$E$2:$E$20000,설정!$B$2)-1),"") | D34: =IFERROR(IF(OR($B34="",COUNTIFS(데이터!$A$2:$A$20000,$A34,데이터!$E$2:$E$20000,설정!$B$3)=0),"",$B34/SUMIFS(데이터!$C$2:$C$20000,데이터!$A$2:$A$20000,$A34,데이터!$E$2:$E$20000,설정!$B$3)-1),"") | E34: =IFERROR(IF(OR($B34="",COUNTIFS(데이터!$A$2:$A$20000,$A34,데이터!$E$2:$E$20000,설정!$B$4)=0),"",$B34/SUMIFS(데이터!$C$2:$C$20000,데이터!$A$2:$A$20000,$A34,데이터!$E$2:$E$20000,설정!$B$4)-1),"") | F34: =IFERROR(IF(OR($B34="",COUNTIFS(데이터!$A$2:$A$20000,$A34,데이터!$E$2:$E$20000,설정!$B$5)=0),"",$B34/SUMIFS(데이터!$C$2:$C$20000,데이터!$A$2:$A$20000,$A34,데이터!$E$2:$E$20000,설정!$B$5)-1),"") | G34: =IFERROR(IF(OR($B34="",COUNTIFS(데이터!$A$2:$A$20000,$A34,데이터!$E$2:$E$20000,설정!$B$6)=0),"",$B34/SUMIFS(데이터!$C$2:$C$20000,데이터!$A$2:$A$20000,$A34,데이터!$E$2:$E$20000,설정!$B$6)-1),"") | H34: =IFERROR(IF(OR($B34="",COUNTIFS(데이터!$A$2:$A$20000,$A34,데이터!$E$2:$E$20000,설정!$B$7)=0),"",$B34/SUMIFS(데이터!$C$2:$C$20000,데이터!$A$2:$A$20000,$A34,데이터!$E$2:$E$20000,설정!$B$7)-1),"") | J34: =IF(C34="","",C34+ROW()*0.000000001) | K34: =IF(D34="","",D34+ROW()*0.000000001) | L34: =IF(E34="","",E34+ROW()*0.000000001) | M34: =IF(F34="","",F34+ROW()*0.000000001) | N34: =IF(G34="","",G34+ROW()*0.000000001) | O34: =IF(H34="","",H34+ROW()*0.000000001)
B35: =IF($A35="","",IF(COUNTIFS(데이터!$A$2:$A$20000,$A35,데이터!$E$2:$E$20000,1)=0,"",SUMIFS(데이터!$C$2:$C$20000,데이터!$A$2:$A$20000,$A35,데이터!$E$2:$E$20000,1))) | C35: =IFERROR(IF(OR($B35="",COUNTIFS(데이터!$A$2:$A$20000,$A35,데이터!$E$2:$E$20000,설정!$B$2)=0),"",$B35/SUMIFS(데이터!$C$2:$C$20000,데이터!$A$2:$A$20000,$A35,데이터!$E$2:$E$20000,설정!$B$2)-1),"") | D35: =IFERROR(IF(OR($B35="",COUNTIFS(데이터!$A$2:$A$20000,$A35,데이터!$E$2:$E$20000,설정!$B$3)=0),"",$B35/SUMIFS(데이터!$C$2:$C$20000,데이터!$A$2:$A$20000,$A35,데이터!$E$2:$E$20000,설정!$B$3)-1),"") | E35: =IFERROR(IF(OR($B35="",COUNTIFS(데이터!$A$2:$A$20000,$A35,데이터!$E$2:$E$20000,설정!$B$4)=0),"",$B35/SUMIFS(데이터!$C$2:$C$20000,데이터!$A$2:$A$20000,$A35,데이터!$E$2:$E$20000,설정!$B$4)-1),"") | F35: =IFERROR(IF(OR($B35="",COUNTIFS(데이터!$A$2:$A$20000,$A35,데이터!$E$2:$E$20000,설정!$B$5)=0),"",$B35/SUMIFS(데이터!$C$2:$C$20000,데이터!$A$2:$A$20000,$A35,데이터!$E$2:$E$20000,설정!$B$5)-1),"") | G35: =IFERROR(IF(OR($B35="",COUNTIFS(데이터!$A$2:$A$20000,$A35,데이터!$E$2:$E$20000,설정!$B$6)=0),"",$B35/SUMIFS(데이터!$C$2:$C$20000,데이터!$A$2:$A$20000,$A35,데이터!$E$2:$E$20000,설정!$B$6)-1),"") | H35: =IFERROR(IF(OR($B35="",COUNTIFS(데이터!$A$2:$A$20000,$A35,데이터!$E$2:$E$20000,설정!$B$7)=0),"",$B35/SUMIFS(데이터!$C$2:$C$20000,데이터!$A$2:$A$20000,$A35,데이터!$E$2:$E$20000,설정!$B$7)-1),"") | J35: =IF(C35="","",C35+ROW()*0.000000001) | K35: =IF(D35="","",D35+ROW()*0.000000001) | L35: =IF(E35="","",E35+ROW()*0.000000001) | M35: =IF(F35="","",F35+ROW()*0.000000001) | N35: =IF(G35="","",G35+ROW()*0.000000001) | O35: =IF(H35="","",H35+ROW()*0.000000001)
B36: =IF($A36="","",IF(COUNTIFS(데이터!$A$2:$A$20000,$A36,데이터!$E$2:$E$20000,1)=0,"",SUMIFS(데이터!$C$2:$C$20000,데이터!$A$2:$A$20000,$A36,데이터!$E$2:$E$20000,1))) | C36: =IFERROR(IF(OR($B36="",COUNTIFS(데이터!$A$2:$A$20000,$A36,데이터!$E$2:$E$20000,설정!$B$2)=0),"",$B36/SUMIFS(데이터!$C$2:$C$20000,데이터!$A$2:$A$20000,$A36,데이터!$E$2:$E$20000,설정!$B$2)-1),"") | D36: =IFERROR(IF(OR($B36="",COUNTIFS(데이터!$A$2:$A$20000,$A36,데이터!$E$2:$E$20000,설정!$B$3)=0),"",$B36/SUMIFS(데이터!$C$2:$C$20000,데이터!$A$2:$A$20000,$A36,데이터!$E$2:$E$20000,설정!$B$3)-1),"") | E36: =IFERROR(IF(OR($B36="",COUNTIFS(데이터!$A$2:$A$20000,$A36,데이터!$E$2:$E$20000,설정!$B$4)=0),"",$B36/SUMIFS(데이터!$C$2:$C$20000,데이터!$A$2:$A$20000,$A36,데이터!$E$2:$E$20000,설정!$B$4)-1),"") | F36: =IFERROR(IF(OR($B36="",COUNTIFS(데이터!$A$2:$A$20000,$A36,데이터!$E$2:$E$20000,설정!$B$5)=0),"",$B36/SUMIFS(데이터!$C$2:$C$20000,데이터!$A$2:$A$20000,$A36,데이터!$E$2:$E$20000,설정!$B$5)-1),"") | G36: =IFERROR(IF(OR($B36="",COUNTIFS(데이터!$A$2:$A$20000,$A36,데이터!$E$2:$E$20000,설정!$B$6)=0),"",$B36/SUMIFS(데이터!$C$2:$C$20000,데이터!$A$2:$A$20000,$A36,데이터!$E$2:$E$20000,설정!$B$6)-1),"") | H36: =IFERROR(IF(OR($B36="",COUNTIFS(데이터!$A$2:$A$20000,$A36,데이터!$E$2:$E$20000,설정!$B$7)=0),"",$B36/SUMIFS(데이터!$C$2:$C$20000,데이터!$A$2:$A$20000,$A36,데이터!$E$2:$E$20000,설정!$B$7)-1),"") | J36: =IF(C36="","",C36+ROW()*0.000000001) | K36: =IF(D36="","",D36+ROW()*0.000000001) | L36: =IF(E36="","",E36+ROW()*0.000000001) | M36: =IF(F36="","",F36+ROW()*0.000000001) | N36: =IF(G36="","",G36+ROW()*0.000000001) | O36: =IF(H36="","",H36+ROW()*0.000000001)
B37: =IF($A37="","",IF(COUNTIFS(데이터!$A$2:$A$20000,$A37,데이터!$E$2:$E$20000,1)=0,"",SUMIFS(데이터!$C$2:$C$20000,데이터!$A$2:$A$20000,$A37,데이터!$E$2:$E$20000,1))) | C37: =IFERROR(IF(OR($B37="",COUNTIFS(데이터!$A$2:$A$20000,$A37,데이터!$E$2:$E$20000,설정!$B$2)=0),"",$B37/SUMIFS(데이터!$C$2:$C$20000,데이터!$A$2:$A$20000,$A37,데이터!$E$2:$E$20000,설정!$B$2)-1),"") | D37: =IFERROR(IF(OR($B37="",COUNTIFS(데이터!$A$2:$A$20000,$A37,데이터!$E$2:$E$20000,설정!$B$3)=0),"",$B37/SUMIFS(데이터!$C$2:$C$20000,데이터!$A$2:$A$20000,$A37,데이터!$E$2:$E$20000,설정!$B$3)-1),"") | E37: =IFERROR(IF(OR($B37="",COUNTIFS(데이터!$A$2:$A$20000,$A37,데이터!$E$2:$E$20000,설정!$B$4)=0),"",$B37/SUMIFS(데이터!$C$2:$C$20000,데이터!$A$2:$A$20000,$A37,데이터!$E$2:$E$20000,설정!$B$4)-1),"") | F37: =IFERROR(IF(OR($B37="",COUNTIFS(데이터!$A$2:$A$20000,$A37,데이터!$E$2:$E$20000,설정!$B$5)=0),"",$B37/SUMIFS(데이터!$C$2:$C$20000,데이터!$A$2:$A$20000,$A37,데이터!$E$2:$E$20000,설정!$B$5)-1),"") | G37: =IFERROR(IF(OR($B37="",COUNTIFS(데이터!$A$2:$A$20000,$A37,데이터!$E$2:$E$20000,설정!$B$6)=0),"",$B37/SUMIFS(데이터!$C$2:$C$20000,데이터!$A$2:$A$20000,$A37,데이터!$E$2:$E$20000,설정!$B$6)-1),"") | H37: =IFERROR(IF(OR($B37="",COUNTIFS(데이터!$A$2:$A$20000,$A37,데이터!$E$2:$E$20000,설정!$B$7)=0),"",$B37/SUMIFS(데이터!$C$2:$C$20000,데이터!$A$2:$A$20000,$A37,데이터!$E$2:$E$20000,설정!$B$7)-1),"") | J37: =IF(C37="","",C37+ROW()*0.000000001) | K37: =IF(D37="","",D37+ROW()*0.000000001) | L37: =IF(E37="","",E37+ROW()*0.000000001) | M37: =IF(F37="","",F37+ROW()*0.000000001) | N37: =IF(G37="","",G37+ROW()*0.000000001) | O37: =IF(H37="","",H37+ROW()*0.000000001)
B38: =IF($A38="","",IF(COUNTIFS(데이터!$A$2:$A$20000,$A38,데이터!$E$2:$E$20000,1)=0,"",SUMIFS(데이터!$C$2:$C$20000,데이터!$A$2:$A$20000,$A38,데이터!$E$2:$E$20000,1))) | C38: =IFERROR(IF(OR($B38="",COUNTIFS(데이터!$A$2:$A$20000,$A38,데이터!$E$2:$E$20000,설정!$B$2)=0),"",$B38/SUMIFS(데이터!$C$2:$C$20000,데이터!$A$2:$A$20000,$A38,데이터!$E$2:$E$20000,설정!$B$2)-1),"") | D38: =IFERROR(IF(OR($B38="",COUNTIFS(데이터!$A$2:$A$20000,$A38,데이터!$E$2:$E$20000,설정!$B$3)=0),"",$B38/SUMIFS(데이터!$C$2:$C$20000,데이터!$A$2:$A$20000,$A38,데이터!$E$2:$E$20000,설정!$B$3)-1),"") | E38: =IFERROR(IF(OR($B38="",COUNTIFS(데이터!$A$2:$A$20000,$A38,데이터!$E$2:$E$20000,설정!$B$4)=0),"",$B38/SUMIFS(데이터!$C$2:$C$20000,데이터!$A$2:$A$20000,$A38,데이터!$E$2:$E$20000,설정!$B$4)-1),"") | F38: =IFERROR(IF(OR($B38="",COUNTIFS(데이터!$A$2:$A$20000,$A38,데이터!$E$2:$E$20000,설정!$B$5)=0),"",$B38/SUMIFS(데이터!$C$2:$C$20000,데이터!$A$2:$A$20000,$A38,데이터!$E$2:$E$20000,설정!$B$5)-1),"") | G38: =IFERROR(IF(OR($B38="",COUNTIFS(데이터!$A$2:$A$20000,$A38,데이터!$E$2:$E$20000,설정!$B$6)=0),"",$B38/SUMIFS(데이터!$C$2:$C$20000,데이터!$A$2:$A$20000,$A38,데이터!$E$2:$E$20000,설정!$B$6)-1),"") | H38: =IFERROR(IF(OR($B38="",COUNTIFS(데이터!$A$2:$A$20000,$A38,데이터!$E$2:$E$20000,설정!$B$7)=0),"",$B38/SUMIFS(데이터!$C$2:$C$20000,데이터!$A$2:$A$20000,$A38,데이터!$E$2:$E$20000,설정!$B$7)-1),"") | J38: =IF(C38="","",C38+ROW()*0.000000001) | K38: =IF(D38="","",D38+ROW()*0.000000001) | L38: =IF(E38="","",E38+ROW()*0.000000001) | M38: =IF(F38="","",F38+ROW()*0.000000001) | N38: =IF(G38="","",G38+ROW()*0.000000001) | O38: =IF(H38="","",H38+ROW()*0.000000001)
B39: =IF($A39="","",IF(COUNTIFS(데이터!$A$2:$A$20000,$A39,데이터!$E$2:$E$20000,1)=0,"",SUMIFS(데이터!$C$2:$C$20000,데이터!$A$2:$A$20000,$A39,데이터!$E$2:$E$20000,1))) | C39: =IFERROR(IF(OR($B39="",COUNTIFS(데이터!$A$2:$A$20000,$A39,데이터!$E$2:$E$20000,설정!$B$2)=0),"",$B39/SUMIFS(데이터!$C$2:$C$20000,데이터!$A$2:$A$20000,$A39,데이터!$E$2:$E$20000,설정!$B$2)-1),"") | D39: =IFERROR(IF(OR($B39="",COUNTIFS(데이터!$A$2:$A$20000,$A39,데이터!$E$2:$E$20000,설정!$B$3)=0),"",$B39/SUMIFS(데이터!$C$2:$C$20000,데이터!$A$2:$A$20000,$A39,데이터!$E$2:$E$20000,설정!$B$3)-1),"") | E39: =IFERROR(IF(OR($B39="",COUNTIFS(데이터!$A$2:$A$20000,$A39,데이터!$E$2:$E$20000,설정!$B$4)=0),"",$B39/SUMIFS(데이터!$C$2:$C$20000,데이터!$A$2:$A$20000,$A39,데이터!$E$2:$E$20000,설정!$B$4)-1),"") | F39: =IFERROR(IF(OR($B39="",COUNTIFS(데이터!$A$2:$A$20000,$A39,데이터!$E$2:$E$20000,설정!$B$5)=0),"",$B39/SUMIFS(데이터!$C$2:$C$20000,데이터!$A$2:$A$20000,$A39,데이터!$E$2:$E$20000,설정!$B$5)-1),"") | G39: =IFERROR(IF(OR($B39="",COUNTIFS(데이터!$A$2:$A$20000,$A39,데이터!$E$2:$E$20000,설정!$B$6)=0),"",$B39/SUMIFS(데이터!$C$2:$C$20000,데이터!$A$2:$A$20000,$A39,데이터!$E$2:$E$20000,설정!$B$6)-1),"") | H39: =IFERROR(IF(OR($B39="",COUNTIFS(데이터!$A$2:$A$20000,$A39,데이터!$E$2:$E$20000,설정!$B$7)=0),"",$B39/SUMIFS(데이터!$C$2:$C$20000,데이터!$A$2:$A$20000,$A39,데이터!$E$2:$E$20000,설정!$B$7)-1),"") | J39: =IF(C39="","",C39+ROW()*0.000000001) | K39: =IF(D39="","",D39+ROW()*0.000000001) | L39: =IF(E39="","",E39+ROW()*0.000000001) | M39: =IF(F39="","",F39+ROW()*0.000000001) | N39: =IF(G39="","",G39+ROW()*0.000000001) | O39: =IF(H39="","",H39+ROW()*0.000000001)
B40: =IF($A40="","",IF(COUNTIFS(데이터!$A$2:$A$20000,$A40,데이터!$E$2:$E$20000,1)=0,"",SUMIFS(데이터!$C$2:$C$20000,데이터!$A$2:$A$20000,$A40,데이터!$E$2:$E$20000,1))) | C40: =IFERROR(IF(OR($B40="",COUNTIFS(데이터!$A$2:$A$20000,$A40,데이터!$E$2:$E$20000,설정!$B$2)=0),"",$B40/SUMIFS(데이터!$C$2:$C$20000,데이터!$A$2:$A$20000,$A40,데이터!$E$2:$E$20000,설정!$B$2)-1),"") | D40: =IFERROR(IF(OR($B40="",COUNTIFS(데이터!$A$2:$A$20000,$A40,데이터!$E$2:$E$20000,설정!$B$3)=0),"",$B40/SUMIFS(데이터!$C$2:$C$20000,데이터!$A$2:$A$20000,$A40,데이터!$E$2:$E$20000,설정!$B$3)-1),"") | E40: =IFERROR(IF(OR($B40="",COUNTIFS(데이터!$A$2:$A$20000,$A40,데이터!$E$2:$E$20000,설정!$B$4)=0),"",$B40/SUMIFS(데이터!$C$2:$C$20000,데이터!$A$2:$A$20000,$A40,데이터!$E$2:$E$20000,설정!$B$4)-1),"") | F40: =IFERROR(IF(OR($B40="",COUNTIFS(데이터!$A$2:$A$20000,$A40,데이터!$E$2:$E$20000,설정!$B$5)=0),"",$B40/SUMIFS(데이터!$C$2:$C$20000,데이터!$A$2:$A$20000,$A40,데이터!$E$2:$E$20000,설정!$B$5)-1),"") | G40: =IFERROR(IF(OR($B40="",COUNTIFS(데이터!$A$2:$A$20000,$A40,데이터!$E$2:$E$20000,설정!$B$6)=0),"",$B40/SUMIFS(데이터!$C$2:$C$20000,데이터!$A$2:$A$20000,$A40,데이터!$E$2:$E$20000,설정!$B$6)-1),"") | H40: =IFERROR(IF(OR($B40="",COUNTIFS(데이터!$A$2:$A$20000,$A40,데이터!$E$2:$E$20000,설정!$B$7)=0),"",$B40/SUMIFS(데이터!$C$2:$C$20000,데이터!$A$2:$A$20000,$A40,데이터!$E$2:$E$20000,설정!$B$7)-1),"") | J40: =IF(C40="","",C40+ROW()*0.000000001) | K40: =IF(D40="","",D40+ROW()*0.000000001) | L40: =IF(E40="","",E40+ROW()*0.000000001) | M40: =IF(F40="","",F40+ROW()*0.000000001) | N40: =IF(G40="","",G40+ROW()*0.000000001) | O40: =IF(H40="","",H40+ROW()*0.000000001)
B41: =IF($A41="","",IF(COUNTIFS(데이터!$A$2:$A$20000,$A41,데이터!$E$2:$E$20000,1)=0,"",SUMIFS(데이터!$C$2:$C$20000,데이터!$A$2:$A$20000,$A41,데이터!$E$2:$E$20000,1))) | C41: =IFERROR(IF(OR($B41="",COUNTIFS(데이터!$A$2:$A$20000,$A41,데이터!$E$2:$E$20000,설정!$B$2)=0),"",$B41/SUMIFS(데이터!$C$2:$C$20000,데이터!$A$2:$A$20000,$A41,데이터!$E$2:$E$20000,설정!$B$2)-1),"") | D41: =IFERROR(IF(OR($B41="",COUNTIFS(데이터!$A$2:$A$20000,$A41,데이터!$E$2:$E$20000,설정!$B$3)=0),"",$B41/SUMIFS(데이터!$C$2:$C$20000,데이터!$A$2:$A$20000,$A41,데이터!$E$2:$E$20000,설정!$B$3)-1),"") | E41: =IFERROR(IF(OR($B41="",COUNTIFS(데이터!$A$2:$A$20000,$A41,데이터!$E$2:$E$20000,설정!$B$4)=0),"",$B41/SUMIFS(데이터!$C$2:$C$20000,데이터!$A$2:$A$20000,$A41,데이터!$E$2:$E$20000,설정!$B$4)-1),"") | F41: =IFERROR(IF(OR($B41="",COUNTIFS(데이터!$A$2:$A$20000,$A41,데이터!$E$2:$E$20000,설정!$B$5)=0),"",$B41/SUMIFS(데이터!$C$2:$C$20000,데이터!$A$2:$A$20000,$A41,데이터!$E$2:$E$20000,설정!$B$5)-1),"") | G41: =IFERROR(IF(OR($B41="",COUNTIFS(데이터!$A$2:$A$20000,$A41,데이터!$E$2:$E$20000,설정!$B$6)=0),"",$B41/SUMIFS(데이터!$C$2:$C$20000,데이터!$A$2:$A$20000,$A41,데이터!$E$2:$E$20000,설정!$B$6)-1),"") | H41: =IFERROR(IF(OR($B41="",COUNTIFS(데이터!$A$2:$A$20000,$A41,데이터!$E$2:$E$20000,설정!$B$7)=0),"",$B41/SUMIFS(데이터!$C$2:$C$20000,데이터!$A$2:$A$20000,$A41,데이터!$E$2:$E$20000,설정!$B$7)-1),"") | J41: =IF(C41="","",C41+ROW()*0.000000001) | K41: =IF(D41="","",D41+ROW()*0.000000001) | L41: =IF(E41="","",E41+ROW()*0.000000001) | M41: =IF(F41="","",F41+ROW()*0.000000001) | N41: =IF(G41="","",G41+ROW()*0.000000001) | O41: =IF(H41="","",H41+ROW()*0.000000001)
B42: =IF($A42="","",IF(COUNTIFS(데이터!$A$2:$A$20000,$A42,데이터!$E$2:$E$20000,1)=0,"",SUMIFS(데이터!$C$2:$C$20000,데이터!$A$2:$A$20000,$A42,데이터!$E$2:$E$20000,1))) | C42: =IFERROR(IF(OR($B42="",COUNTIFS(데이터!$A$2:$A$20000,$A42,데이터!$E$2:$E$20000,설정!$B$2)=0),"",$B42/SUMIFS(데이터!$C$2:$C$20000,데이터!$A$2:$A$20000,$A42,데이터!$E$2:$E$20000,설정!$B$2)-1),"") | D42: =IFERROR(IF(OR($B42="",COUNTIFS(데이터!$A$2:$A$20000,$A42,데이터!$E$2:$E$20000,설정!$B$3)=0),"",$B42/SUMIFS(데이터!$C$2:$C$20000,데이터!$A$2:$A$20000,$A42,데이터!$E$2:$E$20000,설정!$B$3)-1),"") | E42: =IFERROR(IF(OR($B42="",COUNTIFS(데이터!$A$2:$A$20000,$A42,데이터!$E$2:$E$20000,설정!$B$4)=0),"",$B42/SUMIFS(데이터!$C$2:$C$20000,데이터!$A$2:$A$20000,$A42,데이터!$E$2:$E$20000,설정!$B$4)-1),"") | F42: =IFERROR(IF(OR($B42="",COUNTIFS(데이터!$A$2:$A$20000,$A42,데이터!$E$2:$E$20000,설정!$B$5)=0),"",$B42/SUMIFS(데이터!$C$2:$C$20000,데이터!$A$2:$A$20000,$A42,데이터!$E$2:$E$20000,설정!$B$5)-1),"") | G42: =IFERROR(IF(OR($B42="",COUNTIFS(데이터!$A$2:$A$20000,$A42,데이터!$E$2:$E$20000,설정!$B$6)=0),"",$B42/SUMIFS(데이터!$C$2:$C$20000,데이터!$A$2:$A$20000,$A42,데이터!$E$2:$E$20000,설정!$B$6)-1),"") | H42: =IFERROR(IF(OR($B42="",COUNTIFS(데이터!$A$2:$A$20000,$A42,데이터!$E$2:$E$20000,설정!$B$7)=0),"",$B42/SUMIFS(데이터!$C$2:$C$20000,데이터!$A$2:$A$20000,$A42,데이터!$E$2:$E$20000,설정!$B$7)-1),"") | J42: =IF(C42="","",C42+ROW()*0.000000001) | K42: =IF(D42="","",D42+ROW()*0.000000001) | L42: =IF(E42="","",E42+ROW()*0.000000001) | M42: =IF(F42="","",F42+ROW()*0.000000001) | N42: =IF(G42="","",G42+ROW()*0.000000001) | O42: =IF(H42="","",H42+ROW()*0.000000001)
B43: =IF($A43="","",IF(COUNTIFS(데이터!$A$2:$A$20000,$A43,데이터!$E$2:$E$20000,1)=0,"",SUMIFS(데이터!$C$2:$C$20000,데이터!$A$2:$A$20000,$A43,데이터!$E$2:$E$20000,1))) | C43: =IFERROR(IF(OR($B43="",COUNTIFS(데이터!$A$2:$A$20000,$A43,데이터!$E$2:$E$20000,설정!$B$2)=0),"",$B43/SUMIFS(데이터!$C$2:$C$20000,데이터!$A$2:$A$20000,$A43,데이터!$E$2:$E$20000,설정!$B$2)-1),"") | D43: =IFERROR(IF(OR($B43="",COUNTIFS(데이터!$A$2:$A$20000,$A43,데이터!$E$2:$E$20000,설정!$B$3)=0),"",$B43/SUMIFS(데이터!$C$2:$C$20000,데이터!$A$2:$A$20000,$A43,데이터!$E$2:$E$20000,설정!$B$3)-1),"") | E43: =IFERROR(IF(OR($B43="",COUNTIFS(데이터!$A$2:$A$20000,$A43,데이터!$E$2:$E$20000,설정!$B$4)=0),"",$B43/SUMIFS(데이터!$C$2:$C$20000,데이터!$A$2:$A$20000,$A43,데이터!$E$2:$E$20000,설정!$B$4)-1),"") | F43: =IFERROR(IF(OR($B43="",COUNTIFS(데이터!$A$2:$A$20000,$A43,데이터!$E$2:$E$20000,설정!$B$5)=0),"",$B43/SUMIFS(데이터!$C$2:$C$20000,데이터!$A$2:$A$20000,$A43,데이터!$E$2:$E$20000,설정!$B$5)-1),"") | G43: =IFERROR(IF(OR($B43="",COUNTIFS(데이터!$A$2:$A$20000,$A43,데이터!$E$2:$E$20000,설정!$B$6)=0),"",$B43/SUMIFS(데이터!$C$2:$C$20000,데이터!$A$2:$A$20000,$A43,데이터!$E$2:$E$20000,설정!$B$6)-1),"") | H43: =IFERROR(IF(OR($B43="",COUNTIFS(데이터!$A$2:$A$20000,$A43,데이터!$E$2:$E$20000,설정!$B$7)=0),"",$B43/SUMIFS(데이터!$C$2:$C$20000,데이터!$A$2:$A$20000,$A43,데이터!$E$2:$E$20000,설정!$B$7)-1),"") | J43: =IF(C43="","",C43+ROW()*0.000000001) | K43: =IF(D43="","",D43+ROW()*0.000000001) | L43: =IF(E43="","",E43+ROW()*0.000000001) | M43: =IF(F43="","",F43+ROW()*0.000000001) | N43: =IF(G43="","",G43+ROW()*0.000000001) | O43: =IF(H43="","",H43+ROW()*0.000000001)
... B501: =IF($A501="","",IF(COUNTIFS(데이터!$A$2:$A$20000,$A501,데이터!$E$2:$E$20000,1)=0,"",SUMIFS(데이터!$C$2:$C$20000,데이터!$A$2:$A$20000,$A501,데이터!$E$2:$E$20000,1))) | C501: =IFERROR(IF(OR($B501="",COUNTIFS(데이터!$A$2:$A$20000,$A501,데이터!$E$2:$E$20000,설정!$B$2)=0),"",$B501/SUMIFS(데이터!$C$2:$C$20000,데이터!$A$2:$A$20000,$A501,데이터!$E$2:$E$20000,설정!$B$2)-1),"") | D501: =IFERROR(IF(OR($B501="",COUNTIFS(데이터!$A$2:$A$20000,$A501,데이터!$E$2:$E$20000,설정!$B$3)=0),"",$B501/SUMIFS(데이터!$C$2:$C$20000,데이터!$A$2:$A$20000,$A501,데이터!$E$2:$E$20000,설정!$B$3)-1),"") | E501: =IFERROR(IF(OR($B501="",COUNTIFS(데이터!$A$2:$A$20000,$A501,데이터!$E$2:$E$20000,설정!$B$4)=0),"",$B501/SUMIFS(데이터!$C$2:$C$20000,데이터!$A$2:$A$20000,$A501,데이터!$E$2:$E$20000,설정!$B$4)-1),"") | F501: =IFERROR(IF(OR($B501="",COUNTIFS(데이터!$A$2:$A$20000,$A501,데이터!$E$2:$E$20000,설정!$B$5)=0),"",$B501/SUMIFS(데이터!$C$2:$C$20000,데이터!$A$2:$A$20000,$A501,데이터!$E$2:$E$20000,설정!$B$5)-1),"") | G501: =IFERROR(IF(OR($B501="",COUNTIFS(데이터!$A$2:$A$20000,$A501,데이터!$E$2:$E$20000,설정!$B$6)=0),"",$B501/SUMIFS(데이터!$C$2:$C$20000,데이터!$A$2:$A$20000,$A501,데이터!$E$2:$E$20000,설정!$B$6)-1),"") | H501: =IFERROR(IF(OR($B501="",COUNTIFS(데이터!$A$2:$A$20000,$A501,데이터!$E$2:$E$20000,설정!$B$7)=0),"",$B501/SUMIFS(데이터!$C$2:$C$20000,데이터!$A$2:$A$20000,$A501,데이터!$E$2:$E$20000,설정!$B$7)-1),"") | J501: =IF(C501="","",C501+ROW()*0.000000001) | K501: =IF(D501="","",D501+ROW()*0.000000001) | L501: =IF(E501="","",E501+ROW()*0.000000001) | M501: =IF(F501="","",F501+ROW()*0.000000001) | N501: =IF(G501="","",G501+ROW()*0.000000001) | O501: =IF(H501="","",H501+ROW()*0.000000001)

Sheet 순위
A1: 기간별 상위·하위 Top 10 (등락률 = 현재가 ÷ 과거가 − 1, 동률은 목록 순서대로)
A3: 상위 Top 10
A4: 순위 | B4: 1주 전 | C4: 등락률 | D4: 4주 전 | E4: 등락률 | F4: 8주 전 | G4: 등락률 | H4: 12주 전 | I4: 등락률 | J4: 52주 전 | K4: 등락률 | L4: 104주 전 | M4: 등락률
A5: 1 | B5: =IFERROR(INDEX(계산!$A$2:$A$501,MATCH(LARGE(계산!$J$2:$J$501,$A5),계산!$J$2:$J$501,0)),"") | C5: =IFERROR(INDEX(계산!$C$2:$C$501,MATCH(LARGE(계산!$J$2:$J$501,$A5),계산!$J$2:$J$501,0)),"") | D5: =IFERROR(INDEX(계산!$A$2:$A$501,MATCH(LARGE(계산!$K$2:$K$501,$A5),계산!$K$2:$K$501,0)),"") | E5: =IFERROR(INDEX(계산!$D$2:$D$501,MATCH(LARGE(계산!$K$2:$K$501,$A5),계산!$K$2:$K$501,0)),"") | F5: =IFERROR(INDEX(계산!$A$2:$A$501,MATCH(LARGE(계산!$L$2:$L$501,$A5),계산!$L$2:$L$501,0)),"") | G5: =IFERROR(INDEX(계산!$E$2:$E$501,MATCH(LARGE(계산!$L$2:$L$501,$A5),계산!$L$2:$L$501,0)),"") | H5: =IFERROR(INDEX(계산!$A$2:$A$501,MATCH(LARGE(계산!$M$2:$M$501,$A5),계산!$M$2:$M$501,0)),"") | I5: =IFERROR(INDEX(계산!$F$2:$F$501,MATCH(LARGE(계산!$M$2:$M$501,$A5),계산!$M$2:$M$501,0)),"") | J5: =IFERROR(INDEX(계산!$A$2:$A$501,MATCH(LARGE(계산!$N$2:$N$501,$A5),계산!$N$2:$N$501,0)),"") | K5: =IFERROR(INDEX(계산!$G$2:$G$501,MATCH(LARGE(계산!$N$2:$N$501,$A5),계산!$N$2:$N$501,0)),"") | L5: =IFERROR(INDEX(계산!$A$2:$A$501,MATCH(LARGE(계산!$O$2:$O$501,$A5),계산!$O$2:$O$501,0)),"") | M5: =IFERROR(INDEX(계산!$H$2:$H$501,MATCH(LARGE(계산!$O$2:$O$501,$A5),계산!$O$2:$O$501,0)),"")
A6: 2 | B6: =IFERROR(INDEX(계산!$A$2:$A$501,MATCH(LARGE(계산!$J$2:$J$501,$A6),계산!$J$2:$J$501,0)),"") | C6: =IFERROR(INDEX(계산!$C$2:$C$501,MATCH(LARGE(계산!$J$2:$J$501,$A6),계산!$J$2:$J$501,0)),"") | D6: =IFERROR(INDEX(계산!$A$2:$A$501,MATCH(LARGE(계산!$K$2:$K$501,$A6),계산!$K$2:$K$501,0)),"") | E6: =IFERROR(INDEX(계산!$D$2:$D$501,MATCH(LARGE(계산!$K$2:$K$501,$A6),계산!$K$2:$K$501,0)),"") | F6: =IFERROR(INDEX(계산!$A$2:$A$501,MATCH(LARGE(계산!$L$2:$L$501,$A6),계산!$L$2:$L$501,0)),"") | G6: =IFERROR(INDEX(계산!$E$2:$E$501,MATCH(LARGE(계산!$L$2:$L$501,$A6),계산!$L$2:$L$501,0)),"") | H6: =IFERROR(INDEX(계산!$A$2:$A$501,MATCH(LARGE(계산!$M$2:$M$501,$A6),계산!$M$2:$M$501,0)),"") | I6: =IFERROR(INDEX(계산!$F$2:$F$501,MATCH(LARGE(계산!$M$2:$M$501,$A6),계산!$M$2:$M$501,0)),"") | J6: =IFERROR(INDEX(계산!$A$2:$A$501,MATCH(LARGE(계산!$N$2:$N$501,$A6),계산!$N$2:$N$501,0)),"") | K6: =IFERROR(INDEX(계산!$G$2:$G$501,MATCH(LARGE(계산!$N$2:$N$501,$A6),계산!$N$2:$N$501,0)),"") | L6: =IFERROR(INDEX(계산!$A$2:$A$501,MATCH(LARGE(계산!$O$2:$O$501,$A6),계산!$O$2:$O$501,0)),"") | M6: =IFERROR(INDEX(계산!$H$2:$H$501,MATCH(LARGE(계산!$O$2:$O$501,$A6),계산!$O$2:$O$501,0)),"")
A7: 3 | B7: =IFERROR(INDEX(계산!$A$2:$A$501,MATCH(LARGE(계산!$J$2:$J$501,$A7),계산!$J$2:$J$501,0)),"") | C7: =IFERROR(INDEX(계산!$C$2:$C$501,MATCH(LARGE(계산!$J$2:$J$501,$A7),계산!$J$2:$J$501,0)),"") | D7: =IFERROR(INDEX(계산!$A$2:$A$501,MATCH(LARGE(계산!$K$2:$K$501,$A7),계산!$K$2:$K$501,0)),"") | E7: =IFERROR(INDEX(계산!$D$2:$D$501,MATCH(LARGE(계산!$K$2:$K$501,$A7),계산!$K$2:$K$501,0)),"") | F7: =IFERROR(INDEX(계산!$A$2:$A$501,MATCH(LARGE(계산!$L$2:$L$501,$A7),계산!$L$2:$L$501,0)),"") | G7: =IFERROR(INDEX(계산!$E$2:$E$501,MATCH(LARGE(계산!$L$2:$L$501,$A7),계산!$L$2:$L$501,0)),"") | H7: =IFERROR(INDEX(계산!$A$2:$A$501,MATCH(LARGE(계산!$M$2:$M$501,$A7),계산!$M$2:$M$501,0)),"") | I7: =IFERROR(INDEX(계산!$F$2:$F$501,MATCH(LARGE(계산!$M$2:$M$501,$A7),계산!$M$2:$M$501,0)),"") | J7: =IFERROR(INDEX(계산!$A$2:$A$501,MATCH(LARGE(계산!$N$2:$N$501,$A7),계산!$N$2:$N$501,0)),"") | K7: =IFERROR(INDEX(계산!$G$2:$G$501,MATCH(LARGE(계산!$N$2:$N$501,$A7),계산!$N$2:$N$501,0)),"") | L7: =IFERROR(INDEX(계산!$A$2:$A$501,MATCH(LARGE(계산!$O$2:$O$501,$A7),계산!$O$2:$O$501,0)),"") | M7: =IFERROR(INDEX(계산!$H$2:$H$501,MATCH(LARGE(계산!$O$2:$O$501,$A7),계산!$O$2:$O$501,0)),"")
A8: 4 | B8: =IFERROR(INDEX(계산!$A$2:$A$501,MATCH(LARGE(계산!$J$2:$J$501,$A8),계산!$J$2:$J$501,0)),"") | C8: =IFERROR(INDEX(계산!$C$2:$C$501,MATCH(LARGE(계산!$J$2:$J$501,$A8),계산!$J$2:$J$501,0)),"") | D8: =IFERROR(INDEX(계산!$A$2:$A$501,MATCH(LARGE(계산!$K$2:$K$501,$A8),계산!$K$2:$K$501,0)),"") | E8: =IFERROR(INDEX(계산!$D$2:$D$501,MATCH(LARGE(계산!$K$2:$K$501,$A8),계산!$K$2:$K$501,0)),"") | F8: =IFERROR(INDEX(계산!$A$2:$A$501,MATCH(LARGE(계산!$L$2:$L$501,$A8),계산!$L$2:$L$501,0)),"") | G8: =IFERROR(INDEX(계산!$E$2:$E$501,MATCH(LARGE(계산!$L$2:$L$501,$A8),계산!$L$2:$L$501,0)),"") | H8: =IFERROR(INDEX(계산!$A$2:$A$501,MATCH(LARGE(계산!$M$2:$M$501,$A8),계산!$M$2:$M$501,0)),"") | I8: =IFERROR(INDEX(계산!$F$2:$F$501,MATCH(LARGE(계산!$M$2:$M$501,$A8),계산!$M$2:$M$501,0)),"") | J8: =IFERROR(INDEX(계산!$A$2:$A$501,MATCH(LARGE(계산!$N$2:$N$501,$A8),계산!$N$2:$N$501,0)),"") | K8: =IFERROR(INDEX(계산!$G$2:$G$501,MATCH(LARGE(계산!$N$2:$N$501,$A8),계산!$N$2:$N$501,0)),"") | L8: =IFERROR(INDEX(계산!$A$2:$A$501,MATCH(LARGE(계산!$O$2:$O$501,$A8),계산!$O$2:$O$501,0)),"") | M8: =IFERROR(INDEX(계산!$H$2:$H$501,MATCH(LARGE(계산!$O$2:$O$501,$A8),계산!$O$2:$O$501,0)),"")
A9: 5 | B9: =IFERROR(INDEX(계산!$A$2:$A$501,MATCH(LARGE(계산!$J$2:$J$501,$A9),계산!$J$2:$J$501,0)),"") | C9: =IFERROR(INDEX(계산!$C$2:$C$501,MATCH(LARGE(계산!$J$2:$J$501,$A9),계산!$J$2:$J$501,0)),"") | D9: =IFERROR(INDEX(계산!$A$2:$A$501,MATCH(LARGE(계산!$K$2:$K$501,$A9),계산!$K$2:$K$501,0)),"") | E9: =IFERROR(INDEX(계산!$D$2:$D$501,MATCH(LARGE(계산!$K$2:$K$501,$A9),계산!$K$2:$K$501,0)),"") | F9: =IFERROR(INDEX(계산!$A$2:$A$501,MATCH(LARGE(계산!$L$2:$L$501,$A9),계산!$L$2:$L$501,0)),"") | G9: =IFERROR(INDEX(계산!$E$2:$E$501,MATCH(LARGE(계산!$L$2:$L$501,$A9),계산!$L$2:$L$501,0)),"") | H9: =IFERROR(INDEX(계산!$A$2:$A$501,MATCH(LARGE(계산!$M$2:$M$501,$A9),계산!$M$2:$M$501,0)),"") | I9: =IFERROR(INDEX(계산!$F$2:$F$501,MATCH(LARGE(계산!$M$2:$M$501,$A9),계산!$M$2:$M$501,0)),"") | J9: =IFERROR(INDEX(계산!$A$2:$A$501,MATCH(LARGE(계산!$N$2:$N$501,$A9),계산!$N$2:$N$501,0)),"") | K9: =IFERROR(INDEX(계산!$G$2:$G$501,MATCH(LARGE(계산!$N$2:$N$501,$A9),계산!$N$2:$N$501,0)),"") | L9: =IFERROR(INDEX(계산!$A$2:$A$501,MATCH(LARGE(계산!$O$2:$O$501,$A9),계산!$O$2:$O$501,0)),"") | M9: =IFERROR(INDEX(계산!$H$2:$H$501,MATCH(LARGE(계산!$O$2:$O$501,$A9),계산!$O$2:$O$501,0)),"")
A10: 6 | B10: =IFERROR(INDEX(계산!$A$2:$A$501,MATCH(LARGE(계산!$J$2:$J$501,$A10),계산!$J$2:$J$501,0)),"") | C10: =IFERROR(INDEX(계산!$C$2:$C$501,MATCH(LARGE(계산!$J$2:$J$501,$A10),계산!$J$2:$J$501,0)),"") | D10: =IFERROR(INDEX(계산!$A$2:$A$501,MATCH(LARGE(계산!$K$2:$K$501,$A10),계산!$K$2:$K$501,0)),"") | E10: =IFERROR(INDEX(계산!$D$2:$D$501,MATCH(LARGE(계산!$K$2:$K$501,$A10),계산!$K$2:$K$501,0)),"") | F10: =IFERROR(INDEX(계산!$A$2:$A$501,MATCH(LARGE(계산!$L$2:$L$501,$A10),계산!$L$2:$L$501,0)),"") | G10: =IFERROR(INDEX(계산!$E$2:$E$501,MATCH(LARGE(계산!$L$2:$L$501,$A10),계산!$L$2:$L$501,0)),"") | H10: =IFERROR(INDEX(계산!$A$2:$A$501,MATCH(LARGE(계산!$M$2:$M$501,$A10),계산!$M$2:$M$501,0)),"") | I10: =IFERROR(INDEX(계산!$F$2:$F$501,MATCH(LARGE(계산!$M$2:$M$501,$A10),계산!$M$2:$M$501,0)),"") | J10: =IFERROR(INDEX(계산!$A$2:$A$501,MATCH(LARGE(계산!$N$2:$N$501,$A10),계산!$N$2:$N$501,0)),"") | K10: =IFERROR(INDEX(계산!$G$2:$G$501,MATCH(LARGE(계산!$N$2:$N$501,$A10),계산!$N$2:$N$501,0)),"") | L10: =IFERROR(INDEX(계산!$A$2:$A$501,MATCH(LARGE(계산!$O$2:$O$501,$A10),계산!$O$2:$O$501,0)),"") | M10: =IFERROR(INDEX(계산!$H$2:$H$501,MATCH(LARGE(계산!$O$2:$O$501,$A10),계산!$O$2:$O$501,0)),"")
A11: 7 | B11: =IFERROR(INDEX(계산!$A$2:$A$501,MATCH(LARGE(계산!$J$2:$J$501,$A11),계산!$J$2:$J$501,0)),"") | C11: =IFERROR(INDEX(계산!$C$2:$C$501,MATCH(LARGE(계산!$J$2:$J$501,$A11),계산!$J$2:$J$501,0)),"") | D11: =IFERROR(INDEX(계산!$A$2:$A$501,MATCH(LARGE(계산!$K$2:$K$501,$A11),계산!$K$2:$K$501,0)),"") | E11: =IFERROR(INDEX(계산!$D$2:$D$501,MATCH(LARGE(계산!$K$2:$K$501,$A11),계산!$K$2:$K$501,0)),"") | F11: =IFERROR(INDEX(계산!$A$2:$A$501,MATCH(LARGE(계산!$L$2:$L$501,$A11),계산!$L$2:$L$501,0)),"") | G11: =IFERROR(INDEX(계산!$E$2:$E$501,MATCH(LARGE(계산!$L$2:$L$501,$A11),계산!$L$2:$L$501,0)),"") | H11: =IFERROR(INDEX(계산!$A$2:$A$501,MATCH(LARGE(계산!$M$2:$M$501,$A11),계산!$M$2:$M$501,0)),"") | I11: =IFERROR(INDEX(계산!$F$2:$F$501,MATCH(LARGE(계산!$M$2:$M$501,$A11),계산!$M$2:$M$501,0)),"") | J11: =IFERROR(INDEX(계산!$A$2:$A$501,MATCH(LARGE(계산!$N$2:$N$501,$A11),계산!$N$2:$N$501,0)),"") | K11: =IFERROR(INDEX(계산!$G$2:$G$501,MATCH(LARGE(계산!$N$2:$N$501,$A11),계산!$N$2:$N$501,0)),"") | L11: =IFERROR(INDEX(계산!$A$2:$A$501,MATCH(LARGE(계산!$O$2:$O$501,$A11),계산!$O$2:$O$501,0)),"") | M11: =IFERROR(INDEX(계산!$H$2:$H$501,MATCH(LARGE(계산!$O$2:$O$501,$A11),계산!$O$2:$O$501,0)),"")
A12: 8 | B12: =IFERROR(INDEX(계산!$A$2:$A$501,MATCH(LARGE(계산!$J$2:$J$501,$A12),계산!$J$2:$J$501,0)),"") | C12: =IFERROR(INDEX(계산!$C$2:$C$501,MATCH(LARGE(계산!$J$2:$J$501,$A12),계산!$J$2:$J$501,0)),"") | D12: =IFERROR(INDEX(계산!$A$2:$A$501,MATCH(LARGE(계산!$K$2:$K$501,$A12),계산!$K$2:$K$501,0)),"") | E12: =IFERROR(INDEX(계산!$D$2:$D$501,MATCH(LARGE(계산!$K$2:$K$501,$A12),계산!$K$2:$K$501,0)),"") | F12: =IFERROR(INDEX(계산!$A$2:$A$501,MATCH(LARGE(계산!$L$2:$L$501,$A12),계산!$L$2:$L$501,0)),"") | G12: =IFERROR(INDEX(계산!$E$2:$E$501,MATCH(LARGE(계산!$L$2:$L$501,$A12),계산!$L$2:$L$501,0)),"") | H12: =IFERROR(INDEX(계산!$A$2:$A$501,MATCH(LARGE(계산!$M$2:$M$501,$A12),계산!$M$2:$M$501,0)),"") | I12: =IFERROR(INDEX(계산!$F$2:$F$501,MATCH(LARGE(계산!$M$2:$M$501,$A12),계산!$M$2:$M$501,0)),"") | J12: =IFERROR(INDEX(계산!$A$2:$A$501,MATCH(LARGE(계산!$N$2:$N$501,$A12),계산!$N$2:$N$501,0)),"") | K12: =IFERROR(INDEX(계산!$G$2:$G$501,MATCH(LARGE(계산!$N$2:$N$501,$A12),계산!$N$2:$N$501,0)),"") | L12: =IFERROR(INDEX(계산!$A$2:$A$501,MATCH(LARGE(계산!$O$2:$O$501,$A12),계산!$O$2:$O$501,0)),"") | M12: =IFERROR(INDEX(계산!$H$2:$H$501,MATCH(LARGE(계산!$O$2:$O$501,$A12),계산!$O$2:$O$501,0)),"")
A13: 9 | B13: =IFERROR(INDEX(계산!$A$2:$A$501,MATCH(LARGE(계산!$J$2:$J$501,$A13),계산!$J$2:$J$501,0)),"") | C13: =IFERROR(INDEX(계산!$C$2:$C$501,MATCH(LARGE(계산!$J$2:$J$501,$A13),계산!$J$2:$J$501,0)),"") | D13: =IFERROR(INDEX(계산!$A$2:$A$501,MATCH(LARGE(계산!$K$2:$K$501,$A13),계산!$K$2:$K$501,0)),"") | E13: =IFERROR(INDEX(계산!$D$2:$D$501,MATCH(LARGE(계산!$K$2:$K$501,$A13),계산!$K$2:$K$501,0)),"") | F13: =IFERROR(INDEX(계산!$A$2:$A$501,MATCH(LARGE(계산!$L$2:$L$501,$A13),계산!$L$2:$L$501,0)),"") | G13: =IFERROR(INDEX(계산!$E$2:$E$501,MATCH(LARGE(계산!$L$2:$L$501,$A13),계산!$L$2:$L$501,0)),"") | H13: =IFERROR(INDEX(계산!$A$2:$A$501,MATCH(LARGE(계산!$M$2:$M$501,$A13),계산!$M$2:$M$501,0)),"") | I13: =IFERROR(INDEX(계산!$F$2:$F$501,MATCH(LARGE(계산!$M$2:$M$501,$A13),계산!$M$2:$M$501,0)),"") | J13: =IFERROR(INDEX(계산!$A$2:$A$501,MATCH(LARGE(계산!$N$2:$N$501,$A13),계산!$N$2:$N$501,0)),"") | K13: =IFERROR(INDEX(계산!$G$2:$G$501,MATCH(LARGE(계산!$N$2:$N$501,$A13),계산!$N$2:$N$501,0)),"") | L13: =IFERROR(INDEX(계산!$A$2:$A$501,MATCH(LARGE(계산!$O$2:$O$501,$A13),계산!$O$2:$O$501,0)),"") | M13: =IFERROR(INDEX(계산!$H$2:$H$501,MATCH(LARGE(계산!$O$2:$O$501,$A13),계산!$O$2:$O$501,0)),"")
A14: 10 | B14: =IFERROR(INDEX(계산!$A$2:$A$501,MATCH(LARGE(계산!$J$2:$J$501,$A14),계산!$J$2:$J$501,0)),"") | C14: =IFERROR(INDEX(계산!$C$2:$C$501,MATCH(LARGE(계산!$J$2:$J$501,$A14),계산!$J$2:$J$501,0)),"") | D14: =IFERROR(INDEX(계산!$A$2:$A$501,MATCH(LARGE(계산!$K$2:$K$501,$A14),계산!$K$2:$K$501,0)),"") | E14: =IFERROR(INDEX(계산!$D$2:$D$501,MATCH(LARGE(계산!$K$2:$K$501,$A14),계산!$K$2:$K$501,0)),"") | F14: =IFERROR(INDEX(계산!$A$2:$A$501,MATCH(LARGE(계산!$L$2:$L$501,$A14),계산!$L$2:$L$501,0)),"") | G14: =IFERROR(INDEX(계산!$E$2:$E$501,MATCH(LARGE(계산!$L$2:$L$501,$A14),계산!$L$2:$L$501,0)),"") | H14: =IFERROR(INDEX(계산!$A$2:$A$501,MATCH(LARGE(계산!$M$2:$M$501,$A14),계산!$M$2:$M$501,0)),"") | I14: =IFERROR(INDEX(계산!$F$2:$F$501,MATCH(LARGE(계산!$M$2:$M$501,$A14),계산!$M$2:$M$501,0)),"") | J14: =IFERROR(INDEX(계산!$A$2:$A$501,MATCH(LARGE(계산!$N$2:$N$501,$A14),계산!$N$2:$N$501,0)),"") | K14: =IFERROR(INDEX(계산!$G$2:$G$501,MATCH(LARGE(계산!$N$2:$N$501,$A14),계산!$N$2:$N$501,0)),"") | L14: =IFERROR(INDEX(계산!$A$2:$A$501,MATCH(LARGE(계산!$O$2:$O$501,$A14),계산!$O$2:$O$501,0)),"") | M14: =IFERROR(INDEX(계산!$H$2:$H$501,MATCH(LARGE(계산!$O$2:$O$501,$A14),계산!$O$2:$O$501,0)),"")
A17: 하위 Top 10
A18: 순위 | B18: 1주 전 | C18: 등락률 | D18: 4주 전 | E18: 등락률 | F18: 8주 전 | G18: 등락률 | H18: 12주 전 | I18: 등락률 | J18: 52주 전 | K18: 등락률 | L18: 104주 전 | M18: 등락률
A19: 1 | B19: =IFERROR(INDEX(계산!$A$2:$A$501,MATCH(SMALL(계산!$J$2:$J$501,$A19),계산!$J$2:$J$501,0)),"") | C19: =IFERROR(INDEX(계산!$C$2:$C$501,MATCH(SMALL(계산!$J$2:$J$501,$A19),계산!$J$2:$J$501,0)),"") | D19: =IFERROR(INDEX(계산!$A$2:$A$501,MATCH(SMALL(계산!$K$2:$K$501,$A19),계산!$K$2:$K$501,0)),"") | E19: =IFERROR(INDEX(계산!$D$2:$D$501,MATCH(SMALL(계산!$K$2:$K$501,$A19),계산!$K$2:$K$501,0)),"") | F19: =IFERROR(INDEX(계산!$A$2:$A$501,MATCH(SMALL(계산!$L$2:$L$501,$A19),계산!$L$2:$L$501,0)),"") | G19: =IFERROR(INDEX(계산!$E$2:$E$501,MATCH(SMALL(계산!$L$2:$L$501,$A19),계산!$L$2:$L$501,0)),"") | H19: =IFERROR(INDEX(계산!$A$2:$A$501,MATCH(SMALL(계산!$M$2:$M$501,$A19),계산!$M$2:$M$501,0)),"") | I19: =IFERROR(INDEX(계산!$F$2:$F$501,MATCH(SMALL(계산!$M$2:$M$501,$A19),계산!$M$2:$M$501,0)),"") | J19: =IFERROR(INDEX(계산!$A$2:$A$501,MATCH(SMALL(계산!$N$2:$N$501,$A19),계산!$N$2:$N$501,0)),"") | K19: =IFERROR(INDEX(계산!$G$2:$G$501,MATCH(SMALL(계산!$N$2:$N$501,$A19),계산!$N$2:$N$501,0)),"") | L19: =IFERROR(INDEX(계산!$A$2:$A$501,MATCH(SMALL(계산!$O$2:$O$501,$A19),계산!$O$2:$O$501,0)),"") | M19: =IFERROR(INDEX(계산!$H$2:$H$501,MATCH(SMALL(계산!$O$2:$O$501,$A19),계산!$O$2:$O$501,0)),"")
A20: 2 | B20: =IFERROR(INDEX(계산!$A$2:$A$501,MATCH(SMALL(계산!$J$2:$J$501,$A20),계산!$J$2:$J$501,0)),"") | C20: =IFERROR(INDEX(계산!$C$2:$C$501,MATCH(SMALL(계산!$J$2:$J$501,$A20),계산!$J$2:$J$501,0)),"") | D20: =IFERROR(INDEX(계산!$A$2:$A$501,MATCH(SMALL(계산!$K$2:$K$501,$A20),계산!$K$2:$K$501,0)),"") | E20: =IFERROR(INDEX(계산!$D$2:$D$501,MATCH(SMALL(계산!$K$2:$K$501,$A20),계산!$K$2:$K$501,0)),"") | F20: =IFERROR(INDEX(계산!$A$2:$A$501,MATCH(SMALL(계산!$L$2:$L$501,$A20),계산!$L$2:$L$501,0)),"") | G20: =IFERROR(INDEX(계산!$E$2:$E$501,MATCH(SMALL(계산!$L$2:$L$501,$A20),계산!$L$2:$L$501,0)),"") | H20: =IFERROR(INDEX(계산!$A$2:$A$501,MATCH(SMALL(계산!$M$2:$M$501,$A20),계산!$M$2:$M$501,0)),"") | I20: =IFERROR(INDEX(계산!$F$2:$F$501,MATCH(SMALL(계산!$M$2:$M$501,$A20),계산!$M$2:$M$501,0)),"") | J20: =IFERROR(INDEX(계산!$A$2:$A$501,MATCH(SMALL(계산!$N$2:$N$501,$A20),계산!$N$2:$N$501,0)),"") | K20: =IFERROR(INDEX(계산!$G$2:$G$501,MATCH(SMALL(계산!$N$2:$N$501,$A20),계산!$N$2:$N$501,0)),"") | L20: =IFERROR(INDEX(계산!$A$2:$A$501,MATCH(SMALL(계산!$O$2:$O$501,$A20),계산!$O$2:$O$501,0)),"") | M20: =IFERROR(INDEX(계산!$H$2:$H$501,MATCH(SMALL(계산!$O$2:$O$501,$A20),계산!$O$2:$O$501,0)),"")
A21: 3 | B21: =IFERROR(INDEX(계산!$A$2:$A$501,MATCH(SMALL(계산!$J$2:$J$501,$A21),계산!$J$2:$J$501,0)),"") | C21: =IFERROR(INDEX(계산!$C$2:$C$501,MATCH(SMALL(계산!$J$2:$J$501,$A21),계산!$J$2:$J$501,0)),"") | D21: =IFERROR(INDEX(계산!$A$2:$A$501,MATCH(SMALL(계산!$K$2:$K$501,$A21),계산!$K$2:$K$501,0)),"") | E21: =IFERROR(INDEX(계산!$D$2:$D$501,MATCH(SMALL(계산!$K$2:$K$501,$A21),계산!$K$2:$K$501,0)),"") | F21: =IFERROR(INDEX(계산!$A$2:$A$501,MATCH(SMALL(계산!$L$2:$L$501,$A21),계산!$L$2:$L$501,0)),"") | G21: =IFERROR(INDEX(계산!$E$2:$E$501,MATCH(SMALL(계산!$L$2:$L$501,$A21),계산!$L$2:$L$501,0)),"") | H21: =IFERROR(INDEX(계산!$A$2:$A$501,MATCH(SMALL(계산!$M$2:$M$501,$A21),계산!$M$2:$M$501,0)),"") | I21: =IFERROR(INDEX(계산!$F$2:$F$501,MATCH(SMALL(계산!$M$2:$M$501,$A21),계산!$M$2:$M$501,0)),"") | J21: =IFERROR(INDEX(계산!$A$2:$A$501,MATCH(SMALL(계산!$N$2:$N$501,$A21),계산!$N$2:$N$501,0)),"") | K21: =IFERROR(INDEX(계산!$G$2:$G$501,MATCH(SMALL(계산!$N$2:$N$501,$A21),계산!$N$2:$N$501,0)),"") | L21: =IFERROR(INDEX(계산!$A$2:$A$501,MATCH(SMALL(계산!$O$2:$O$501,$A21),계산!$O$2:$O$501,0)),"") | M21: =IFERROR(INDEX(계산!$H$2:$H$501,MATCH(SMALL(계산!$O$2:$O$501,$A21),계산!$O$2:$O$501,0)),"")
A22: 4 | B22: =IFERROR(INDEX(계산!$A$2:$A$501,MATCH(SMALL(계산!$J$2:$J$501,$A22),계산!$J$2:$J$501,0)),"") | C22: =IFERROR(INDEX(계산!$C$2:$C$501,MATCH(SMALL(계산!$J$2:$J$501,$A22),계산!$J$2:$J$501,0)),"") | D22: =IFERROR(INDEX(계산!$A$2:$A$501,MATCH(SMALL(계산!$K$2:$K$501,$A22),계산!$K$2:$K$501,0)),"") | E22: =IFERROR(INDEX(계산!$D$2:$D$501,MATCH(SMALL(계산!$K$2:$K$501,$A22),계산!$K$2:$K$501,0)),"") | F22: =IFERROR(INDEX(계산!$A$2:$A$501,MATCH(SMALL(계산!$L$2:$L$501,$A22),계산!$L$2:$L$501,0)),"") | G22: =IFERROR(INDEX(계산!$E$2:$E$501,MATCH(SMALL(계산!$L$2:$L$501,$A22),계산!$L$2:$L$501,0)),"") | H22: =IFERROR(INDEX(계산!$A$2:$A$501,MATCH(SMALL(계산!$M$2:$M$501,$A22),계산!$M$2:$M$501,0)),"") | I22: =IFERROR(INDEX(계산!$F$2:$F$501,MATCH(SMALL(계산!$M$2:$M$501,$A22),계산!$M$2:$M$501,0)),"") | J22: =IFERROR(INDEX(계산!$A$2:$A$501,MATCH(SMALL(계산!$N$2:$N$501,$A22),계산!$N$2:$N$501,0)),"") | K22: =IFERROR(INDEX(계산!$G$2:$G$501,MATCH(SMALL(계산!$N$2:$N$501,$A22),계산!$N$2:$N$501,0)),"") | L22: =IFERROR(INDEX(계산!$A$2:$A$501,MATCH(SMALL(계산!$O$2:$O$501,$A22),계산!$O$2:$O$501,0)),"") | M22: =IFERROR(INDEX(계산!$H$2:$H$501,MATCH(SMALL(계산!$O$2:$O$501,$A22),계산!$O$2:$O$501,0)),"")
A23: 5 | B23: =IFERROR(INDEX(계산!$A$2:$A$501,MATCH(SMALL(계산!$J$2:$J$501,$A23),계산!$J$2:$J$501,0)),"") | C23: =IFERROR(INDEX(계산!$C$2:$C$501,MATCH(SMALL(계산!$J$2:$J$501,$A23),계산!$J$2:$J$501,0)),"") | D23: =IFERROR(INDEX(계산!$A$2:$A$501,MATCH(SMALL(계산!$K$2:$K$501,$A23),계산!$K$2:$K$501,0)),"") | E23: =IFERROR(INDEX(계산!$D$2:$D$501,MATCH(SMALL(계산!$K$2:$K$501,$A23),계산!$K$2:$K$501,0)),"") | F23: =IFERROR(INDEX(계산!$A$2:$A$501,MATCH(SMALL(계산!$L$2:$L$501,$A23),계산!$L$2:$L$501,0)),"") | G23: =IFERROR(INDEX(계산!$E$2:$E$501,MATCH(SMALL(계산!$L$2:$L$501,$A23),계산!$L$2:$L$501,0)),"") | H23: =IFERROR(INDEX(계산!$A$2:$A$501,MATCH(SMALL(계산!$M$2:$M$501,$A23),계산!$M$2:$M$501,0)),"") | I23: =IFERROR(INDEX(계산!$F$2:$F$501,MATCH(SMALL(계산!$M$2:$M$501,$A23),계산!$M$2:$M$501,0)),"") | J23: =IFERROR(INDEX(계산!$A$2:$A$501,MATCH(SMALL(계산!$N$2:$N$501,$A23),계산!$N$2:$N$501,0)),"") | K23: =IFERROR(INDEX(계산!$G$2:$G$501,MATCH(SMALL(계산!$N$2:$N$501,$A23),계산!$N$2:$N$501,0)),"") | L23: =IFERROR(INDEX(계산!$A$2:$A$501,MATCH(SMALL(계산!$O$2:$O$501,$A23),계산!$O$2:$O$501,0)),"") | M23: =IFERROR(INDEX(계산!$H$2:$H$501,MATCH(SMALL(계산!$O$2:$O$501,$A23),계산!$O$2:$O$501,0)),"")
A24: 6 | B24: =IFERROR(INDEX(계산!$A$2:$A$501,MATCH(SMALL(계산!$J$2:$J$501,$A24),계산!$J$2:$J$501,0)),"") | C24: =IFERROR(INDEX(계산!$C$2:$C$501,MATCH(SMALL(계산!$J$2:$J$501,$A24),계산!$J$2:$J$501,0)),"") | D24: =IFERROR(INDEX(계산!$A$2:$A$501,MATCH(SMALL(계산!$K$2:$K$501,$A24),계산!$K$2:$K$501,0)),"") | E24: =IFERROR(INDEX(계산!$D$2:$D$501,MATCH(SMALL(계산!$K$2:$K$501,$A24),계산!$K$2:$K$501,0)),"") | F24: =IFERROR(INDEX(계산!$A$2:$A$501,MATCH(SMALL(계산!$L$2:$L$501,$A24),계산!$L$2:$L$501,0)),"") | G24: =IFERROR(INDEX(계산!$E$2:$E$501,MATCH(SMALL(계산!$L$2:$L$501,$A24),계산!$L$2:$L$501,0)),"") | H24: =IFERROR(INDEX(계산!$A$2:$A$501,MATCH(SMALL(계산!$M$2:$M$501,$A24),계산!$M$2:$M$501,0)),"") | I24: =IFERROR(INDEX(계산!$F$2:$F$501,MATCH(SMALL(계산!$M$2:$M$501,$A24),계산!$M$2:$M$501,0)),"") | J24: =IFERROR(INDEX(계산!$A$2:$A$501,MATCH(SMALL(계산!$N$2:$N$501,$A24),계산!$N$2:$N$501,0)),"") | K24: =IFERROR(INDEX(계산!$G$2:$G$501,MATCH(SMALL(계산!$N$2:$N$501,$A24),계산!$N$2:$N$501,0)),"") | L24: =IFERROR(INDEX(계산!$A$2:$A$501,MATCH(SMALL(계산!$O$2:$O$501,$A24),계산!$O$2:$O$501,0)),"") | M24: =IFERROR(INDEX(계산!$H$2:$H$501,MATCH(SMALL(계산!$O$2:$O$501,$A24),계산!$O$2:$O$501,0)),"")
